Workbook

Sheet Rosters
D1: KIRK/DAVID (11) | G1: STEVE L. (43) | J1: JOHN (9) | M1: KEVIN (2) | P1: DANNY/JOEY (10) | S1: GREG/GRIFFIN (7)
A2: QB | B2: =IF(C2="*", SUMIF(Scoring!B2:B13, Rosters!D2, Scoring!M2:M13), "") | D2: Caleb Williams (Chi) | E2: =IF(F2="*", SUMIF(Scoring!B14:B25, Rosters!G2, Scoring!M14:M25), "") | G2: Jayden Daniels (Was) | H2: =IF(I2="*", SUMIF(Scoring!B26:B37, Rosters!J2, Scoring!M26:M37), "") -> 9 | I2: * | J2: Bo Nix (Den) | K2: =IF(L2="*", SUMIF(Scoring!B38:B49, Rosters!M2, Scoring!M38:M49), "") -> 12 | L2: * | M2: Jalen Hurts (Phi) | N2: =IF(O2="*", SUMIF(Scoring!B50:B61, Rosters!P2, Scoring!M50:M61), "") -> 11 | O2: * | P2: Josh Allen (Buf) | Q2: =IF(R2="*", SUMIF(Scoring!B62:B73, Rosters!S2, Scoring!M62:M73), "") -> 6 | R2: * | S2: Baker Mayfield (TB)
B3: =IF(C3="*", SUMIF(Scoring!B2:B13, Rosters!D3, Scoring!M2:M13), "") -> 26 | C3: * | D3: Jordan Love (GB) | E3: =IF(F3="*", SUMIF(Scoring!B14:B25, Rosters!G3, Scoring!M14:M25), "") -> 0 | F3: * | G3: Tua Tagovailoa (Mia) | H3: =IF(I3="*", SUMIF(Scoring!B26:B37, Rosters!J3, Scoring!M26:M37), "") | J3: Kyler Murray (Arz) | K3: =IF(L3="*", SUMIF(Scoring!B38:B49, Rosters!M3, Scoring!M38:M49), "") | M3: Matthew Stafford (LAR) | N3: =IF(O3="*", SUMIF(Scoring!B50:B61, Rosters!P3, Scoring!M50:M61), "") | P3: Jaxson Dart (NYG) | Q3: =IF(R3="*", SUMIF(Scoring!B62:B73, Rosters!S3, Scoring!M62:M73), "") | S3: Tyler Shough (NO)
B4: =IF(C4="*", SUMIF(Scoring!B2:B13, Rosters!D4, Scoring!M2:M13), "") | D4: Brock Purdy (SF) | E4: =IF(F4="*", SUMIF(Scoring!B14:B25, Rosters!G4, Scoring!M14:M25), "") | G4: Joe Flacco (Cin) | H4: =IF(I4="*", SUMIF(Scoring!B26:B37, Rosters!J4, Scoring!M26:M37), "") | J4: Dak Prescott (Dal) | K4: =IF(L4="*", SUMIF(Scoring!B38:B49, Rosters!M4, Scoring!M38:M49), "") | M4: Dillon Gabriel (Cle) | N4: =IF(O4="*", SUMIF(Scoring!B50:B61, Rosters!P4, Scoring!M50:M61), "") | P4: Mac Jones (SF) | Q4: =IF(R4="*", SUMIF(Scoring!B62:B73, Rosters!S4, Scoring!M62:M73), "") | S4: Shedeur Sanders (Cle)
H5: =IF(I5="*", SUMIF(Scoring!B26:B37, Rosters!J5, Scoring!M26:M37), "")
A6: RB | B6: =IF(C6="*", SUMIF(Scoring!B2:B13, Rosters!D6, Scoring!M2:M13), "") -> 2 | C6: * | D6: Josh Jacobs (GB) | E6: =IF(F6="*", SUMIF(Scoring!B14:B25, Rosters!G6, Scoring!M14:M25), "") -> 0 | F6: * | G6: Jahmyr Gibbs (Det) | H6: =IF(I6="*", SUMIF(Scoring!B26:B37, Rosters!J6, Scoring!M26:M37), "") -> 6 | I6: * | J6: Kyren Williams (LAR) | K6: =IF(L6="*", SUMIF(Scoring!B38:B49, Rosters!M6, Scoring!M38:M49), "") -> 10 | L6: * | M6: De'Von Achane (Mia) | N6: =IF(O6="*", SUMIF(Scoring!B50:B61, Rosters!P6, Scoring!M50:M61), "") | P6: Omarion Hampton (LAC) | Q6: =IF(R6="*", SUMIF(Scoring!B62:B73, Rosters!S6, Scoring!M62:M73), "") | S6: Chuba Hubbard (Car)
B7: =IF(C7="*", SUMIF(Scoring!B2:B13, Rosters!D7, Scoring!M2:M13), "") | D7: Travis Etienne (Jax) | E7: =IF(F7="*", SUMIF(Scoring!B14:B25, Rosters!G7, Scoring!M14:M25), "") | G7: D'Andre Swift (Chi) | H7: =IF(I7="*", SUMIF(Scoring!B26:B37, Rosters!J7, Scoring!M26:M37), "") | J7: Nick Chubb (Hou) | K7: =IF(L7="*", SUMIF(Scoring!B38:B49, Rosters!M7, Scoring!M38:M49), "") | M7: Tyrone Tracy (NYG) | N7: =IF(O7="*", SUMIF(Scoring!B50:B61, Rosters!P7, Scoring!M50:M61), "") | P7: JK Dobbins (Den) | Q7: =IF(R7="*", SUMIF(Scoring!B62:B73, Rosters!S7, Scoring!M62:M73), "") | S7: Trey Benson (Arz)
B8: =IF(C8="*", SUMIF(Scoring!B2:B13, Rosters!D8, Scoring!M2:M13), "") | D8: Jordan Mason (Min) | E8: =IF(F8="*", SUMIF(Scoring!B14:B25, Rosters!G8, Scoring!M14:M25), "") -> 0 | F8: * | G8: Isiah Pacheco (KC) | H8: =IF(I8="*", SUMIF(Scoring!B26:B37, Rosters!J8, Scoring!M26:M37), "") -> 8 | I8: * | J8: Blake Corum (LAR) | K8: =IF(L8="*", SUMIF(Scoring!B38:B49, Rosters!M8, Scoring!M38:M49), "") | M8: Rachaad White (TB) | N8: =IF(O8="*", SUMIF(Scoring!B50:B61, Rosters!P8, Scoring!M50:M61), "") -> 6 | O8: * | P8: Zach Charbonnet (Sea) | Q8: =IF(R8="*", SUMIF(Scoring!B62:B73, Rosters!S8, Scoring!M62:M73), "") -> 4 | R8: * | S8: Quinshon Judkins (CLE)
B9: =IF(C9="*", SUMIF(Scoring!B2:B13, Rosters!D9, Scoring!M2:M13), "") -> 12 | C9: * | D9: RJ Harvey (Den) | E9: =IF(F9="*", SUMIF(Scoring!B14:B25, Rosters!G9, Scoring!M14:M25), "") | G9: Kaleb Johnson (Pit) | H9: =IF(I9="*", SUMIF(Scoring!B26:B37, Rosters!J9, Scoring!M26:M37), "") | J9: Joe Mixon (Hou) | K9: =IF(L9="*", SUMIF(Scoring!B38:B49, Rosters!M9, Scoring!M38:M49), "") -> 0 | L9: * | M9: Woody Marks (Hou) | N9: =IF(O9="*", SUMIF(Scoring!B50:B61, Rosters!P9, Scoring!M50:M61), "") -> 0 | O9: * | P9: Tyjae Spears (Ten) | Q9: =IF(R9="*", SUMIF(Scoring!B62:B73, Rosters!S9, Scoring!M62:M73), "") -> 6 | R9: * | S9: Jaylen Warren (Pit)
H10: =IF(I10="*", SUMIF(Scoring!B26:B37, Rosters!J10, Scoring!M26:M37), "")
A11: WR | B11: =IF(C11="*", SUMIF(Scoring!B2:B13, Rosters!D11, Scoring!M2:M13), "") | D11: Justin Jefferson (Min) | E11: =IF(F11="*", SUMIF(Scoring!B14:B25, Rosters!G11, Scoring!M14:M25), "") | G11: DK Metcalf (Pit) | H11: =IF(I11="*", SUMIF(Scoring!B26:B37, Rosters!J11, Scoring!M26:M37), "") -> 3 | I11: * | J11: Ja'Marr Chase (Cin) | K11: =IF(L11="*", SUMIF(Scoring!B38:B49, Rosters!M11, Scoring!M38:M49), "") | M11: Zay Flowers (Bal) | N11: =IF(O11="*", SUMIF(Scoring!B50:B61, Rosters!P11, Scoring!M50:M61), "") -> 0 | O11: * | P11: Amon-Ra St. Brown (Det) | Q11: =IF(R11="*", SUMIF(Scoring!B62:B73, Rosters!S11, Scoring!M62:M73), "") -> 0 | R11: * | S11: Jaxon Smith-Njigba (Sea)
B12: =IF(C12="*", SUMIF(Scoring!B2:B13, Rosters!D12, Scoring!M2:M13), "") -> 0 | C12: * | D12: Puka Nacua (LAR) | E12: =IF(F12="*", SUMIF(Scoring!B14:B25, Rosters!G12, Scoring!M14:M25), "") | G12: Jameson Williams (Det) | H12: =IF(I12="*", SUMIF(Scoring!B26:B37, Rosters!J12, Scoring!M26:M37), "") | J12: Tee Higgins (Cin) | K12: =IF(L12="*", SUMIF(Scoring!B38:B49, Rosters!M12, Scoring!M38:M49), "") | M12: Jordan Addison (Min) | N12: =IF(O12="*", SUMIF(Scoring!B50:B61, Rosters!P12, Scoring!M50:M61), "") -> 0 | O12: * | P12: Marvin Harrison (Arz) | Q12: =IF(R12="*", SUMIF(Scoring!B62:B73, Rosters!S12, Scoring!M62:M73), "") -> 14 | R12: * | S12: Rashee Rice (KC)
B13: =IF(C13="*", SUMIF(Scoring!B2:B13, Rosters!D13, Scoring!M2:M13), "") -> 12 | C13: * | D13: Davante Adams (LAR) | E13: =IF(F13="*", SUMIF(Scoring!B14:B25, Rosters!G13, Scoring!M14:M25), "") -> 8 | F13: * | G13: Christian Watson (GB) | H13: =IF(I13="*", SUMIF(Scoring!B26:B37, Rosters!J13, Scoring!M26:M37), "") | J13: Courtland Sutton (Den) | K13: =IF(L13="*", SUMIF(Scoring!B38:B49, Rosters!M13, Scoring!M38:M49), "") -> 0 | L13: * | M13: Deebo Samuel (Was) | N13: =IF(O13="*", SUMIF(Scoring!B50:B61, Rosters!P13, Scoring!M50:M61), "") | P13: Luther Burden (Chi) | Q13: =IF(R13="*", SUMIF(Scoring!B62:B73, Rosters!S13, Scoring!M62:M73), "") | S13: DJ Moore (Chi)
B14: =IF(C14="*", SUMIF(Scoring!B2:B13, Rosters!D14, Scoring!M2:M13), "") | D14: Romeo Doubs (GB) | E14: =IF(F14="*", SUMIF(Scoring!B14:B25, Rosters!G14, Scoring!M14:M25), "") -> 6 | F14: * | G14: Tet McMillan (Car) | H14: =IF(I14="*", SUMIF(Scoring!B26:B37, Rosters!J14, Scoring!M26:M37), "") -> 0 | I14: * | J14: Michael Pittman (Ind) | K14: =IF(L14="*", SUMIF(Scoring!B38:B49, Rosters!M14, Scoring!M38:M49), "") -> 0 | L14: * | M14: Emeka Egbuka (TB) | N14: =IF(O14="*", SUMIF(Scoring!B50:B61, Rosters!P14, Scoring!M50:M61), "") | P14: Quentin Johnston (LAC) | Q14: =IF(R14="*", SUMIF(Scoring!B62:B73, Rosters!S14, Scoring!M62:M73), "") | S14: Keon Coleman (Buf)
H15: =IF(I15="*", SUMIF(Scoring!B26:B37, Rosters!J15, Scoring!M26:M37), "")
A16: TE | B16: =IF(C16="*", SUMIF(Scoring!B2:B13, Rosters!D16, Scoring!M2:M13), "") | D16: Dalton Schultz (Hou) | E16: =IF(F16="*", SUMIF(Scoring!B14:B25, Rosters!G16, Scoring!M14:M25), "") | G16: Sam LaPorta (Det) | H16: =IF(I16="*", SUMIF(Scoring!B26:B37, Rosters!J16, Scoring!M26:M37), "") | J16: Tucker Kraft (GB) | K16: =IF(L16="*", SUMIF(Scoring!B38:B49, Rosters!M16, Scoring!M38:M49), "") -> 6 | L16: * | M16: Travis Kelce (KC) | N16: =IF(O16="*", SUMIF(Scoring!B50:B61, Rosters!P16, Scoring!M50:M61), "") | P16: TJ Hockenson (Min) | Q16: =IF(R16="*", SUMIF(Scoring!B62:B73, Rosters!S16, Scoring!M62:M73), "") -> 0 | R16: * | S16: Jake Ferguson (Dal)
B17: =IF(C17="*", SUMIF(Scoring!B2:B13, Rosters!D17, Scoring!M2:M13), "") | D17: Jake Tonges (SF) | E17: =IF(F17="*", SUMIF(Scoring!B14:B25, Rosters!G17, Scoring!M14:M25), "") -> 0 | F17: * | G17: Gunnar Helm (Ten) | H17: =IF(I17="*", SUMIF(Scoring!B26:B37, Rosters!J17, Scoring!M26:M37), "") -> 0 | I17: * | J17: Dallas Goedert (Phi) | K17: =IF(L17="*", SUMIF(Scoring!B38:B49, Rosters!M17, Scoring!M38:M49), "") | M17: Jonnu Smith (Pit) | N17: =IF(O17="*", SUMIF(Scoring!B50:B61, Rosters!P17, Scoring!M50:M61), "") | P17: Juwan Johnson (NO) | Q17: =IF(R17="*", SUMIF(Scoring!B62:B73, Rosters!S17, Scoring!M62:M73), "") | S17: Cade Otton (TB)
B18: =IF(C18="*", SUMIF(Scoring!B2:B13, Rosters!D18, Scoring!M2:M13), "") -> 0 | C18: * | D18: Darren Waller (Mia) | E18: =IF(F18="*", SUMIF(Scoring!B14:B25, Rosters!G18, Scoring!M14:M25), "") | G18: Evan Engram (Den) | H18: =IF(I18="*", SUMIF(Scoring!B26:B37, Rosters!J18, Scoring!M26:M37), "") | J18: Tyler Warren (Ind) | K18: =IF(L18="*", SUMIF(Scoring!B38:B49, Rosters!M18, Scoring!M38:M49), "") | M18: Theo Johnson (NYG) | N18: =IF(O18="*", SUMIF(Scoring!B50:B61, Rosters!P18, Scoring!M50:M61), "") -> 6 | O18: * | P18: Brenton Strange (Jax) | Q18: =IF(R18="*", SUMIF(Scoring!B62:B73, Rosters!S18, Scoring!M62:M73), "") | S18: Mason Taylor (NYJ)
H19: =IF(I19="*", SUMIF(Scoring!B26:B37, Rosters!J19, Scoring!M26:M37), "")
A20: K | B20: =IF(C20="*", SUMIF(Scoring!B2:B13, Rosters!D20, Scoring!M2:M13), "") -> 0 | C20: * | D20: Jake Elliott (Phi) | E20: =IF(F20="*", SUMIF(Scoring!B14:B25, Rosters!G20, Scoring!M14:M25), "") -> 8 | F20: * | G20: Brandon Aubrey (Dal) | H20: =IF(I20="*", SUMIF(Scoring!B26:B37, Rosters!J20, Scoring!M26:M37), "") -> 8 | I20: * | J20: Cameron Dicker (LAC) | K20: =IF(L20="*", SUMIF(Scoring!B38:B49, Rosters!M20, Scoring!M38:M49), "") -> 1 | L20: * | M20: Chris Boswell (Pit) | N20: =IF(O20="*", SUMIF(Scoring!B50:B61, Rosters!P20, Scoring!M50:M61), "") -> 2 | O20: * | P20: Tyler Loop (Bal) | Q20: =IF(R20="*", SUMIF(Scoring!B62:B73, Rosters!S20, Scoring!M62:M73), "") | S20: Brandon McManus (GB)
B21: =IF(C21="*", SUMIF(Scoring!B2:B13, Rosters!D21, Scoring!M2:M13), "") | D21: Will Reichard (Min) | E21: =IF(F21="*", SUMIF(Scoring!B14:B25, Rosters!G21, Scoring!M14:M25), "") | G21: Chase McLaughlin (TB) | H21: =IF(I21="*", SUMIF(Scoring!B26:B37, Rosters!J21, Scoring!M26:M37), "") | J21: Matt Gay (Was) | K21: =IF(L21="*", SUMIF(Scoring!B38:B49, Rosters!M21, Scoring!M38:M49), "") | M21: Will Lutz (Den) | N21: =IF(O21="*", SUMIF(Scoring!B50:B61, Rosters!P21, Scoring!M50:M61), "") | P21: Eddy Pineiro (SF) | Q21: =IF(R21="*", SUMIF(Scoring!B62:B73, Rosters!S21, Scoring!M62:M73), "") -> 15 | R21: * | S21: Jason Myers (Sea)
H22: =IF(I22="*", SUMIF(Scoring!B26:B37, Rosters!J22, Scoring!M26:M37), "")
A23: DF | B23: =IF(C23="*", SUMIF(Scoring!B2:B13, Rosters!D23, Scoring!M2:M13), "") | D23: Baltimore | E23: =IF(F23="*", SUMIF(Scoring!B14:B25, Rosters!G23, Scoring!M14:M25), "") -> 3 | F23: * | G23: Houston | H23: =IF(I23="*", SUMIF(Scoring!B26:B37, Rosters!J23, Scoring!M26:M37), "") -> 13 | I23: * | J23: San Francisco | K23: =IF(L23="*", SUMIF(Scoring!B38:B49, Rosters!M23, Scoring!M38:M49), "") -> 0 | L23: * | M23: LA Rams | N23: =IF(O23="*", SUMIF(Scoring!B50:B61, Rosters!P23, Scoring!M50:M61), "") | P23: Kansas City | Q23: =IF(R23="*", SUMIF(Scoring!B62:B73, Rosters!S23, Scoring!M62:M73), "") | S23: Tampa Bay
B24: =IF(C24="*", SUMIF(Scoring!B2:B13, Rosters!D24, Scoring!M2:M13), "") -> 4 | C24: * | D24: Denver | E24: =IF(F24="*", SUMIF(Scoring!B14:B25, Rosters!G24, Scoring!M14:M25), "") | G24: Arizona | H24: =IF(I24="*", SUMIF(Scoring!B26:B37, Rosters!J24, Scoring!M26:M37), "") | J24: Chicago | K24: =IF(L24="*", SUMIF(Scoring!B38:B49, Rosters!M24, Scoring!M38:M49), "") | M24: Jacksonville | N24: =IF(O24="*", SUMIF(Scoring!B50:B61, Rosters!P24, Scoring!M50:M61), "") -> 6 | O24: * | P24: New England | Q24: =IF(R24="*", SUMIF(Scoring!B62:B73, Rosters!S24, Scoring!M62:M73), "") -> 26 | R24: * | S24: Seattle
H25: =IF(I25="*", SUMIF(Scoring!B26:B37, Rosters!J25, Scoring!M26:M37), "")
A26: HC | B26: =IF(C26="*", SUMIF(Scoring!B2:B13, Rosters!D26, Scoring!M2:M13), "") -> 0 | C26: * | D26: Sean McVay (LAR) | E26: =IF(F26="*", SUMIF(Scoring!B14:B25, Rosters!G26, Scoring!M14:M25), "") -> 0 | F26: * | G26: Dan Campbell (Det) | H26: =IF(I26="*", SUMIF(Scoring!B26:B37, Rosters!J26, Scoring!M26:M37), "") -> 0 | I26: * | J26: John Harbaugh (Bal) | K26: =IF(L26="*", SUMIF(Scoring!B38:B49, Rosters!M26, Scoring!M38:M49), "") -> 5 | L26: * | M26: Kyle Shanahan (SF) | N26: =IF(O26="*", SUMIF(Scoring!B50:B61, Rosters!P26, Scoring!M50:M61), "") | P26: Sean Payton (Den) | Q26: =IF(R26="*", SUMIF(Scoring!B62:B73, Rosters!S26, Scoring!M62:M73), "") | S26: Mike Tomlin (Pit)
B27: =IF(C27="*", SUMIF(Scoring!B2:B13, Rosters!D27, Scoring!M2:M13), "") | D27: Ben Johnson (Chi) | E27: =IF(F27="*", SUMIF(Scoring!B14:B25, Rosters!G27, Scoring!M14:M25), "") | G27: DeMeco Ryans (Hou) | H27: =IF(I27="*", SUMIF(Scoring!B26:B37, Rosters!J27, Scoring!M26:M37), "") | J27: Shane Steichen (Ind) | K27: =IF(L27="*", SUMIF(Scoring!B38:B49, Rosters!M27, Scoring!M38:M49), "") | M27: Kevin Stefanski (Cle) | N27: =IF(O27="*", SUMIF(Scoring!B50:B61, Rosters!P27, Scoring!M50:M61), "") -> 4 | O27: * | P27: Mike Vrabel (NE) | Q27: =IF(R27="*", SUMIF(Scoring!B62:B73, Rosters!S27, Scoring!M62:M73), "") -> 4 | R27: * | S27: Todd Bowles (TB)
D29: =SUM(B2:B28) -> 56 | G29: =SUM(E2:E28) -> 25 | J29: =SUM(H2:H28) -> 47 | M29: =SUM(K2:K28) -> 34 | P29: =SUM(N2:N28) -> 35 | S29: =SUM(Q2:Q28) -> 75
A31: PH | D31: 407-5858 cell | G31: 435-4605 cell | J31: 388-7371 cell | M31: 913-3136 cell | P31: 289-8690 (D) | S31: (925) 518-5773 cell
P32: 325-1289 (J)
A34: TS
D39: ERIC/JEFF (12) | G39: ANDREW (1) | J39: WES/BILL (5) | M39: KEMP/A/M (8) | P39: JARRETT/MATT (6) | S39: ADAM (4)
A40: QB | B40: =IF(C40="*", SUMIF(Scoring!B74:B85, Rosters!D40, Scoring!M74:M85), "") -> 11 | C40: * | D40: Justin Herbert (LAC) | E40: =IF(F40="*", SUMIF(Scoring!B86:B97, Rosters!G40, Scoring!M86:M97), "") -> 16 | F40: * | G40: Trevor Lawrence (Jax) | H40: =IF(I40="*", SUMIF(Scoring!B98:B109, Rosters!J40, Scoring!M98:M109), "") -> 15 | I40: * | J40: Joe Burrow (Cin) | K40: =IF(L40="*", SUMIF(Scoring!B110:B121, Rosters!M40, Scoring!M110:M121), "") -> 0 | L40: * | M40: Lamar Jackson (Bal) | N40: =IF(O40="*", SUMIF(Scoring!B122:B133, Rosters!P40, Scoring!M122:M133), "") -> 27 | O40: * | P40: Patrick Mahomes (KC) | Q40: =IF(R40="*", SUMIF(Scoring!B134:B145, Rosters!S40, Scoring!M134:M145), "") | S40: CJ Stroud (Hou)
B41: =IF(C41="*", SUMIF(Scoring!B74:B85, Rosters!D41, Scoring!M74:M85), "") | D41: Aaron Rodgers (Pit) | E41: =IF(F41="*", SUMIF(Scoring!B86:B97, Rosters!G41, Scoring!M86:M97), "") | G41: JJ McCarthy (Min) | H41: =IF(I41="*", SUMIF(Scoring!B98:B109, Rosters!J41, Scoring!M98:M109), "") | J41: Sam Darnold (Sea) | K41: =IF(L41="*", SUMIF(Scoring!B110:B121, Rosters!M41, Scoring!M110:M121), "") | M41: Drake Maye (NE) | N41: =IF(O41="*", SUMIF(Scoring!B122:B133, Rosters!P41, Scoring!M122:M133), "") | P41: Justin Fields (NYJ) | Q41: =IF(R41="*", SUMIF(Scoring!B134:B145, Rosters!S41, Scoring!M134:M145), "") -> 15 | R41: * | S41: Jared Goff (Det)
B42: =IF(C42="*", SUMIF(Scoring!B74:B85, Rosters!D42, Scoring!M74:M85), "") | D42: Jameis Winston (NYG) | E42: =IF(F42="*", SUMIF(Scoring!B86:B97, Rosters!G42, Scoring!M86:M97), "") | G42: Cam Ward (Ten) | H42: =IF(I42="*", SUMIF(Scoring!B98:B109, Rosters!J42, Scoring!M98:M109), "") | J42: Jalen Milroe (Sea) | K42: =IF(L42="*", SUMIF(Scoring!B110:B121, Rosters!M42, Scoring!M110:M121), "") | M42: Michael Penix (Atl) | N42: =IF(O42="*", SUMIF(Scoring!B122:B133, Rosters!P42, Scoring!M122:M133), "") | P42: Bryce Young (Car) | Q42: =IF(R42="*", SUMIF(Scoring!B134:B145, Rosters!S42, Scoring!M134:M145), "") | S42: Daniel Jones (Ind)
A44: RB | B44: =IF(C44="*", SUMIF(Scoring!B74:B85, Rosters!D44, Scoring!M74:M85), "") -> 0 | C44: * | D44: TreVeyon Henderson (NE) | E44: =IF(F44="*", SUMIF(Scoring!B86:B97, Rosters!G44, Scoring!M86:M97), "") | G44: Christian McCaffrey (SF) | H44: =IF(I44="*", SUMIF(Scoring!B98:B109, Rosters!J44, Scoring!M98:M109), "") -> 11 | I44: * | J44: Bijan Robinson (Atl) | K44: =IF(L44="*", SUMIF(Scoring!B110:B121, Rosters!M44, Scoring!M110:M121), "") -> 2 | L44: * | M44: Jonathan Taylor (Ind) | N44: =IF(O44="*", SUMIF(Scoring!B122:B133, Rosters!P44, Scoring!M122:M133), "") -> 2 | O44: * | P44: Chase Brown (Cin) | Q44: =IF(R44="*", SUMIF(Scoring!B134:B145, Rosters!S44, Scoring!M134:M145), "") -> 0 | R44: * | S44: Saquon Barkley (Phi)
B45: =IF(C45="*", SUMIF(Scoring!B74:B85, Rosters!D45, Scoring!M74:M85), "") | D45: Brian Robinson (SF) | E45: =IF(F45="*", SUMIF(Scoring!B86:B97, Rosters!G45, Scoring!M86:M97), "") -> 0 | F45: * | G45: Kenneth Walker III (Sea) | H45: =IF(I45="*", SUMIF(Scoring!B98:B109, Rosters!J45, Scoring!M98:M109), "") | J45: Bucky Irving (TB) | K45: =IF(L45="*", SUMIF(Scoring!B110:B121, Rosters!M45, Scoring!M110:M121), "") -> 8 | L45: * | M45: Derrick Henry (Bal) | N45: =IF(O45="*", SUMIF(Scoring!B122:B133, Rosters!P45, Scoring!M122:M133), "") | P45: Alvin Kamara (NO) | Q45: =IF(R45="*", SUMIF(Scoring!B134:B145, Rosters!S45, Scoring!M134:M145), "") -> 0 | R45: * | S45: Ashton Jeanty (LV)
B46: =IF(C46="*", SUMIF(Scoring!B74:B85, Rosters!D46, Scoring!M74:M85), "") | D46: Jacory Croskey-Merritt (Was) | E46: =IF(F46="*", SUMIF(Scoring!B86:B97, Rosters!G46, Scoring!M86:M97), "") -> 6 | F46: * | G46: David Montgomery (Det) | H46: =IF(I46="*", SUMIF(Scoring!B98:B109, Rosters!J46, Scoring!M98:M109), "") -> 4 | I46: * | J46: James Cook (Buf) | K46: =IF(L46="*", SUMIF(Scoring!B110:B121, Rosters!M46, Scoring!M110:M121), "") | M46: Aaron Jones (Min) | N46: =IF(O46="*", SUMIF(Scoring!B122:B133, Rosters!P46, Scoring!M122:M133), "") -> 0 | O46: * | P46: Tony Pollard (TEN) | Q46: =IF(R46="*", SUMIF(Scoring!B134:B145, Rosters!S46, Scoring!M134:M145), "") | S46: Breece Hall (NYJ)
B47: =IF(C47="*", SUMIF(Scoring!B74:B85, Rosters!D47, Scoring!M74:M85), "") -> 6 | C47: * | D47: Javonte Williams (Dal) | E47: =IF(F47="*", SUMIF(Scoring!B86:B97, Rosters!G47, Scoring!M86:M97), "") | G47: Najee Harris (LAC) | H47: =IF(I47="*", SUMIF(Scoring!B98:B109, Rosters!J47, Scoring!M98:M109), "") | J47: Bhayshul Tuten (Jax) | K47: =IF(L47="*", SUMIF(Scoring!B110:B121, Rosters!M47, Scoring!M110:M121), "") | M47: Rico Dowdle (Car) | N47: =IF(O47="*", SUMIF(Scoring!B122:B133, Rosters!P47, Scoring!M122:M133), "") | P47: Cam Skattebo (NYG) | Q47: =IF(R47="*", SUMIF(Scoring!B134:B145, Rosters!S47, Scoring!M134:M145), "") | S47: Kimani Vidal (LAC)
A49: WR | B49: =IF(C49="*", SUMIF(Scoring!B74:B85, Rosters!D49, Scoring!M74:M85), "") -> 8 | C49: * | D49: Nico Collins (Hou) | E49: =IF(F49="*", SUMIF(Scoring!B86:B97, Rosters!G49, Scoring!M86:M97), "") -> 6 | F49: * | G49: Ladd McConkey (LAC) | H49: =IF(I49="*", SUMIF(Scoring!B98:B109, Rosters!J49, Scoring!M98:M109), "") -> 0 | I49: * | J49: Brian Thomas Jr. (Jax) | K49: =IF(L49="*", SUMIF(Scoring!B110:B121, Rosters!M49, Scoring!M110:M121), "") -> 0 | L49: * | M49: DeVonta Smith (Phi) | N49: =IF(O49="*", SUMIF(Scoring!B122:B133, Rosters!P49, Scoring!M122:M133), "") | P49: Malik Nabers (NYG) | Q49: =IF(R49="*", SUMIF(Scoring!B134:B145, Rosters!S49, Scoring!M134:M145), "") | S49: Garrett Wilson (NYJ)
...

Sheet Matchups
A1: =if(H2=1, Scoring!A86, if(H2=2, Scoring!A26, if(H2=3, Scoring!A98, if(H2=4, Scoring!A14, if(H2=5, Scoring!A62, if(H2=6, Scoring!A122, if(H2=7, Scoring!A38, if(H2=8, Scoring!A110, if(H2=9, Scoring!A2, if(H2=10, Scoring!A74, if(H2=11, Scoring!A134, Scoring!A50))))))))))) -> K/A/M | D1: =if(I2=1, Scoring!A86, if(I2=2, Scoring!A26, if(I2=3, Scoring!A98, if(I2=4, Scoring!A14, if(I2=5, Scoring!A62, if(I2=6, Scoring!A122, if(I2=7, Scoring!A38, if(I2=8, Scoring!A110, if(I2=9, Scoring!A2, if(I2=10, Scoring!A74, if(I2=11, Scoring!A134, Scoring!A50))))))))))) -> Steve L | L1: Key
A2: =if($H$2=1, Scoring!B86, if($H$2=2, Scoring!B26, if($H$2=3, Scoring!B98, if($H$2=4, Scoring!B14, if($H$2=5, Scoring!B62, if($H$2=6, Scoring!B122, if($H$2=7, Scoring!B38, if($H$2=8, Scoring!B110, if($H$2=9, Scoring!B2, if($H$2=10, Scoring!B74, if($H$2=11, Scoring!B134, Scoring!B50))))))))))) -> Lamar Jackson (Bal) | B2: =if($H$2=1, Scoring!M86, if($H$2=2, Scoring!M26, if($H$2=3, Scoring!M98, if($H$2=4, Scoring!M14, if($H$2=5, Scoring!M62, if($H$2=6, Scoring!M122, if($H$2=7, Scoring!M38, if($H$2=8, Scoring!M110, if($H$2=9, Scoring!M2, if($H$2=10, Scoring!M74, if($H$2=11, Scoring!M134, Scoring!M50))))))))))) -> 0 | D2: =if($I$2=1, Scoring!B86, if($I$2=2, Scoring!B26, if($I$2=3, Scoring!B98, if($I$2=4, Scoring!B14, if($I$2=5, Scoring!B62, if($I$2=6, Scoring!B122, if($I$2=7, Scoring!B38, if($I$2=8, Scoring!B110, if($I$2=9, Scoring!B2, if($I$2=10, Scoring!B74, if($I$2=11, Scoring!B134, Scoring!B50))))))))))) -> Tua Tagovailoa (Mia) | E2: =if($I$2=1, Scoring!M86, if($I$2=2, Scoring!M26, if($I$2=3, Scoring!M98, if($I$2=4, Scoring!M14, if($I$2=5, Scoring!M62, if($I$2=6, Scoring!M122, if($I$2=7, Scoring!M38, if($I$2=8, Scoring!M110, if($I$2=9, Scoring!M2, if($I$2=10, Scoring!M74, if($I$2=11, Scoring!M134, Scoring!M50))))))))))) -> 0 | H2: 8 | I2: 4 | L2: 1=andrew
A3: =if($H$2=1, Scoring!B87, if($H$2=2, Scoring!B27, if($H$2=3, Scoring!B99, if($H$2=4, Scoring!B15, if($H$2=5, Scoring!B63, if($H$2=6, Scoring!B123, if($H$2=7, Scoring!B39, if($H$2=8, Scoring!B111, if($H$2=9, Scoring!B3, if($H$2=10, Scoring!B75, if($H$2=11, Scoring!B135, Scoring!B51))))))))))) -> Jonathan Taylor (Ind) | B3: =if($H$2=1, Scoring!M87, if($H$2=2, Scoring!M27, if($H$2=3, Scoring!M99, if($H$2=4, Scoring!M15, if($H$2=5, Scoring!M63, if($H$2=6, Scoring!M123, if($H$2=7, Scoring!M39, if($H$2=8, Scoring!M111, if($H$2=9, Scoring!M3, if($H$2=10, Scoring!M75, if($H$2=11, Scoring!M135, Scoring!M51))))))))))) -> 2 | D3: =if($I$2=1, Scoring!B87, if($I$2=2, Scoring!B27, if($I$2=3, Scoring!B99, if($I$2=4, Scoring!B15, if($I$2=5, Scoring!B63, if($I$2=6, Scoring!B123, if($I$2=7, Scoring!B39, if($I$2=8, Scoring!B111, if($I$2=9, Scoring!B3, if($I$2=10, Scoring!B75, if($I$2=11, Scoring!B135, Scoring!B51))))))))))) -> Jahmyr Gibbs (Det) | E3: =if($I$2=1, Scoring!M87, if($I$2=2, Scoring!M27, if($I$2=3, Scoring!M99, if($I$2=4, Scoring!M15, if($I$2=5, Scoring!M63, if($I$2=6, Scoring!M123, if($I$2=7, Scoring!M39, if($I$2=8, Scoring!M111, if($I$2=9, Scoring!M3, if($I$2=10, Scoring!M75, if($I$2=11, Scoring!M135, Scoring!M51))))))))))) -> 0 | H3: 12 | I3: 9 | L3: 2=John
A4: =if($H$2=1, Scoring!B88, if($H$2=2, Scoring!B28, if($H$2=3, Scoring!B100, if($H$2=4, Scoring!B16, if($H$2=5, Scoring!B64, if($H$2=6, Scoring!B124, if($H$2=7, Scoring!B40, if($H$2=8, Scoring!B112, if($H$2=9, Scoring!B4, if($H$2=10, Scoring!B76, if($H$2=11, Scoring!B136, Scoring!B52))))))))))) -> Derrick Henry (Bal) | B4: =if($H$2=1, Scoring!M88, if($H$2=2, Scoring!M28, if($H$2=3, Scoring!M100, if($H$2=4, Scoring!M16, if($H$2=5, Scoring!M64, if($H$2=6, Scoring!M124, if($H$2=7, Scoring!M40, if($H$2=8, Scoring!M112, if($H$2=9, Scoring!M4, if($H$2=10, Scoring!M76, if($H$2=11, Scoring!M136, Scoring!M52))))))))))) -> 8 | D4: =if($I$2=1, Scoring!B88, if($I$2=2, Scoring!B28, if($I$2=3, Scoring!B100, if($I$2=4, Scoring!B16, if($I$2=5, Scoring!B64, if($I$2=6, Scoring!B124, if($I$2=7, Scoring!B40, if($I$2=8, Scoring!B112, if($I$2=9, Scoring!B4, if($I$2=10, Scoring!B76, if($I$2=11, Scoring!B136, Scoring!B52))))))))))) -> Isiah Pacheco (KC) | E4: =if($I$2=1, Scoring!M88, if($I$2=2, Scoring!M28, if($I$2=3, Scoring!M100, if($I$2=4, Scoring!M16, if($I$2=5, Scoring!M64, if($I$2=6, Scoring!M124, if($I$2=7, Scoring!M40, if($I$2=8, Scoring!M112, if($I$2=9, Scoring!M4, if($I$2=10, Scoring!M76, if($I$2=11, Scoring!M136, Scoring!M52))))))))))) -> 0 | H4: 7 | I4: 3 | L4: 3=w/b
A5: =if($H$2=1, Scoring!B89, if($H$2=2, Scoring!B29, if($H$2=3, Scoring!B101, if($H$2=4, Scoring!B17, if($H$2=5, Scoring!B65, if($H$2=6, Scoring!B125, if($H$2=7, Scoring!B41, if($H$2=8, Scoring!B113, if($H$2=9, Scoring!B5, if($H$2=10, Scoring!B77, if($H$2=11, Scoring!B137, Scoring!B53))))))))))) -> DeVonta Smith (Phi) | B5: =if($H$2=1, Scoring!M89, if($H$2=2, Scoring!M29, if($H$2=3, Scoring!M101, if($H$2=4, Scoring!M17, if($H$2=5, Scoring!M65, if($H$2=6, Scoring!M125, if($H$2=7, Scoring!M41, if($H$2=8, Scoring!M113, if($H$2=9, Scoring!M5, if($H$2=10, Scoring!M77, if($H$2=11, Scoring!M137, Scoring!M53))))))))))) -> 0 | D5: =if($I$2=1, Scoring!B89, if($I$2=2, Scoring!B29, if($I$2=3, Scoring!B101, if($I$2=4, Scoring!B17, if($I$2=5, Scoring!B65, if($I$2=6, Scoring!B125, if($I$2=7, Scoring!B41, if($I$2=8, Scoring!B113, if($I$2=9, Scoring!B5, if($I$2=10, Scoring!B77, if($I$2=11, Scoring!B137, Scoring!B53))))))))))) -> Christian Watson (GB) | E5: =if($I$2=1, Scoring!M89, if($I$2=2, Scoring!M29, if($I$2=3, Scoring!M101, if($I$2=4, Scoring!M17, if($I$2=5, Scoring!M65, if($I$2=6, Scoring!M125, if($I$2=7, Scoring!M41, if($I$2=8, Scoring!M113, if($I$2=9, Scoring!M5, if($I$2=10, Scoring!M77, if($I$2=11, Scoring!M137, Scoring!M53))))))))))) -> 8 | H5: 10 | I5: 1 | L5: 4=SL
A6: =if($H$2=1, Scoring!B90, if($H$2=2, Scoring!B30, if($H$2=3, Scoring!B102, if($H$2=4, Scoring!B18, if($H$2=5, Scoring!B66, if($H$2=6, Scoring!B126, if($H$2=7, Scoring!B42, if($H$2=8, Scoring!B114, if($H$2=9, Scoring!B6, if($H$2=10, Scoring!B78, if($H$2=11, Scoring!B138, Scoring!B54))))))))))) -> George Pickens (Dal) | B6: =if($H$2=1, Scoring!M90, if($H$2=2, Scoring!M30, if($H$2=3, Scoring!M102, if($H$2=4, Scoring!M18, if($H$2=5, Scoring!M66, if($H$2=6, Scoring!M126, if($H$2=7, Scoring!M42, if($H$2=8, Scoring!M114, if($H$2=9, Scoring!M6, if($H$2=10, Scoring!M78, if($H$2=11, Scoring!M138, Scoring!M54))))))))))) -> 4 | D6: =if($I$2=1, Scoring!B90, if($I$2=2, Scoring!B30, if($I$2=3, Scoring!B102, if($I$2=4, Scoring!B18, if($I$2=5, Scoring!B66, if($I$2=6, Scoring!B126, if($I$2=7, Scoring!B42, if($I$2=8, Scoring!B114, if($I$2=9, Scoring!B6, if($I$2=10, Scoring!B78, if($I$2=11, Scoring!B138, Scoring!B54))))))))))) -> Tet McMillan (Car) | E6: =if($I$2=1, Scoring!M90, if($I$2=2, Scoring!M30, if($I$2=3, Scoring!M102, if($I$2=4, Scoring!M18, if($I$2=5, Scoring!M66, if($I$2=6, Scoring!M126, if($I$2=7, Scoring!M42, if($I$2=8, Scoring!M114, if($I$2=9, Scoring!M6, if($I$2=10, Scoring!M78, if($I$2=11, Scoring!M138, Scoring!M54))))))))))) -> 6 | H6: 6 | I6: 2 | L6: 5=G/G
A7: =if($H$2=1, Scoring!B91, if($H$2=2, Scoring!B31, if($H$2=3, Scoring!B103, if($H$2=4, Scoring!B19, if($H$2=5, Scoring!B67, if($H$2=6, Scoring!B127, if($H$2=7, Scoring!B43, if($H$2=8, Scoring!B115, if($H$2=9, Scoring!B7, if($H$2=10, Scoring!B79, if($H$2=11, Scoring!B139, Scoring!B55))))))))))) -> George Kittle (SF) | B7: =if($H$2=1, Scoring!M91, if($H$2=2, Scoring!M31, if($H$2=3, Scoring!M103, if($H$2=4, Scoring!M19, if($H$2=5, Scoring!M67, if($H$2=6, Scoring!M127, if($H$2=7, Scoring!M43, if($H$2=8, Scoring!M115, if($H$2=9, Scoring!M7, if($H$2=10, Scoring!M79, if($H$2=11, Scoring!M139, Scoring!M55))))))))))) -> 2 | D7: =if($I$2=1, Scoring!B91, if($I$2=2, Scoring!B31, if($I$2=3, Scoring!B103, if($I$2=4, Scoring!B19, if($I$2=5, Scoring!B67, if($I$2=6, Scoring!B127, if($I$2=7, Scoring!B43, if($I$2=8, Scoring!B115, if($I$2=9, Scoring!B7, if($I$2=10, Scoring!B79, if($I$2=11, Scoring!B139, Scoring!B55))))))))))) -> Gunnar Helm (Ten) | E7: =if($I$2=1, Scoring!M91, if($I$2=2, Scoring!M31, if($I$2=3, Scoring!M103, if($I$2=4, Scoring!M19, if($I$2=5, Scoring!M67, if($I$2=6, Scoring!M127, if($I$2=7, Scoring!M43, if($I$2=8, Scoring!M115, if($I$2=9, Scoring!M7, if($I$2=10, Scoring!M79, if($I$2=11, Scoring!M139, Scoring!M55))))))))))) -> 0 | H7: 11 | I7: 5 | L7: 6=J/M
A8: =if($H$2=1, Scoring!B93, if($H$2=2, Scoring!B33, if($H$2=3, Scoring!B105, if($H$2=4, Scoring!B21, if($H$2=5, Scoring!B69, if($H$2=6, Scoring!B129, if($H$2=7, Scoring!B45, if($H$2=8, Scoring!B117, if($H$2=9, Scoring!B9, if($H$2=10, Scoring!B81, if($H$2=11, Scoring!B141, Scoring!B57))))))))))) -> Cam Little (Jax) | B8: =if($H$2=1, Scoring!M93, if($H$2=2, Scoring!M33, if($H$2=3, Scoring!M105, if($H$2=4, Scoring!M21, if($H$2=5, Scoring!M69, if($H$2=6, Scoring!M129, if($H$2=7, Scoring!M45, if($H$2=8, Scoring!M117, if($H$2=9, Scoring!M9, if($H$2=10, Scoring!M81, if($H$2=11, Scoring!M141, Scoring!M57))))))))))) -> 5 | D8: =if($I$2=1, Scoring!B93, if($I$2=2, Scoring!B33, if($I$2=3, Scoring!B105, if($I$2=4, Scoring!B21, if($I$2=5, Scoring!B69, if($I$2=6, Scoring!B129, if($I$2=7, Scoring!B45, if($I$2=8, Scoring!B117, if($I$2=9, Scoring!B9, if($I$2=10, Scoring!B81, if($I$2=11, Scoring!B141, Scoring!B57))))))))))) -> Brandon Aubrey (Dal) | E8: =if($I$2=1, Scoring!M93, if($I$2=2, Scoring!M33, if($I$2=3, Scoring!M105, if($I$2=4, Scoring!M21, if($I$2=5, Scoring!M69, if($I$2=6, Scoring!M129, if($I$2=7, Scoring!M45, if($I$2=8, Scoring!M117, if($I$2=9, Scoring!M9, if($I$2=10, Scoring!M81, if($I$2=11, Scoring!M141, Scoring!M57))))))))))) -> 8 | L8: 7=KL
A9: =if($H$2=1, Scoring!B95, if($H$2=2, Scoring!B35, if($H$2=3, Scoring!B107, if($H$2=4, Scoring!B23, if($H$2=5, Scoring!B71, if($H$2=6, Scoring!B131, if($H$2=7, Scoring!B47, if($H$2=8, Scoring!B119, if($H$2=9, Scoring!B11, if($H$2=10, Scoring!B83, if($H$2=11, Scoring!B143, Scoring!B59))))))))))) -> LA Chargers | B9: =if($H$2=1, Scoring!M95, if($H$2=2, Scoring!M35, if($H$2=3, Scoring!M107, if($H$2=4, Scoring!M23, if($H$2=5, Scoring!M71, if($H$2=6, Scoring!M131, if($H$2=7, Scoring!M47, if($H$2=8, Scoring!M119, if($H$2=9, Scoring!M11, if($H$2=10, Scoring!M83, if($H$2=11, Scoring!M143, Scoring!M59))))))))))) -> 9 | D9: =if($I$2=1, Scoring!B95, if($I$2=2, Scoring!B35, if($I$2=3, Scoring!B107, if($I$2=4, Scoring!B23, if($I$2=5, Scoring!B71, if($I$2=6, Scoring!B131, if($I$2=7, Scoring!B47, if($I$2=8, Scoring!B119, if($I$2=9, Scoring!B11, if($I$2=10, Scoring!B83, if($I$2=11, Scoring!B143, Scoring!B59))))))))))) -> Houston | E9: =if($I$2=1, Scoring!M95, if($I$2=2, Scoring!M35, if($I$2=3, Scoring!M107, if($I$2=4, Scoring!M23, if($I$2=5, Scoring!M71, if($I$2=6, Scoring!M131, if($I$2=7, Scoring!M47, if($I$2=8, Scoring!M119, if($I$2=9, Scoring!M11, if($I$2=10, Scoring!M83, if($I$2=11, Scoring!M143, Scoring!M59))))))))))) -> 3 | L9: 8=KAM
A10: =if($H$2=1, Scoring!B97, if($H$2=2, Scoring!B37, if($H$2=3, Scoring!B109, if($H$2=4, Scoring!B25, if($H$2=5, Scoring!B73, if($H$2=6, Scoring!B133, if($H$2=7, Scoring!B49, if($H$2=8, Scoring!B121, if($H$2=9, Scoring!B13, if($H$2=10, Scoring!B85, if($H$2=11, Scoring!B145, Scoring!B61))))))))))) -> Raheem Morris (Atl) | B10: =if($H$2=1, Scoring!M97, if($H$2=2, Scoring!M37, if($H$2=3, Scoring!M109, if($H$2=4, Scoring!M25, if($H$2=5, Scoring!M73, if($H$2=6, Scoring!M133, if($H$2=7, Scoring!M49, if($H$2=8, Scoring!M121, if($H$2=9, Scoring!M13, if($H$2=10, Scoring!M85, if($H$2=11, Scoring!M145, Scoring!M61))))))))))) -> 0 | D10: =if($I$2=1, Scoring!B97, if($I$2=2, Scoring!B37, if($I$2=3, Scoring!B109, if($I$2=4, Scoring!B25, if($I$2=5, Scoring!B73, if($I$2=6, Scoring!B133, if($I$2=7, Scoring!B49, if($I$2=8, Scoring!B121, if($I$2=9, Scoring!B13, if($I$2=10, Scoring!B85, if($I$2=11, Scoring!B145, Scoring!B61))))))))))) -> Dan Campbell (Det) | E10: =if($I$2=1, Scoring!M97, if($I$2=2, Scoring!M37, if($I$2=3, Scoring!M109, if($I$2=4, Scoring!M25, if($I$2=5, Scoring!M73, if($I$2=6, Scoring!M133, if($I$2=7, Scoring!M49, if($I$2=8, Scoring!M121, if($I$2=9, Scoring!M13, if($I$2=10, Scoring!M85, if($I$2=11, Scoring!M145, Scoring!M61))))))))))) -> 0 | L10: 9=K/D
B11: =sum(B2:B10) -> 30 | E11: =sum(E2:E10) -> 25 | L11: 10=E/J
L12: 11=Adam
A13: =if(H3=1, Scoring!A86, if(H3=2, Scoring!A26, if(H3=3, Scoring!A98, if(H3=4, Scoring!A14, if(H3=5, Scoring!A62, if(H3=6, Scoring!A122, if(H3=7, Scoring!A38, if(H3=8, Scoring!A110, if(H3=9, Scoring!A2, if(H3=10, Scoring!A74, if(H3=11, Scoring!A134, Scoring!A50))))))))))) -> D/J | D13: =if(I3=1, Scoring!A86, if(I3=2, Scoring!A26, if(I3=3, Scoring!A98, if(I3=4, Scoring!A14, if(I3=5, Scoring!A62, if(I3=6, Scoring!A122, if(I3=7, Scoring!A38, if(I3=8, Scoring!A110, if(I3=9, Scoring!A2, if(I3=10, Scoring!A74, if(I3=11, Scoring!A134, Scoring!A50))))))))))) -> Kirk/D | L13: 12=D/J
A14: =if($H$3=1, Scoring!B86, if($H$3=2, Scoring!B26, if($H$3=3, Scoring!B98, if($H$3=4, Scoring!B14, if($H$3=5, Scoring!B62, if($H$3=6, Scoring!B122, if($H$3=7, Scoring!B38, if($H$3=8, Scoring!B110, if($H$3=9, Scoring!B2, if($H$3=10, Scoring!B74, if($H$3=11, Scoring!B134, Scoring!B50))))))))))) -> Josh Allen (Buf) | B14: =if($H$3=1, Scoring!M86, if($H$3=2, Scoring!M26, if($H$3=3, Scoring!M98, if($H$3=4, Scoring!M14, if($H$3=5, Scoring!M62, if($H$3=6, Scoring!M122, if($H$3=7, Scoring!M38, if($H$3=8, Scoring!M110, if($H$3=9, Scoring!M2, if($H$3=10, Scoring!M74, if($H$3=11, Scoring!M134, Scoring!M50))))))))))) -> 11 | D14: =if($I$3=1, Scoring!B86, if($I$3=2, Scoring!B26, if($I$3=3, Scoring!B98, if($I$3=4, Scoring!B14, if($I$3=5, Scoring!B62, if($I$3=6, Scoring!B122, if($I$3=7, Scoring!B38, if($I$3=8, Scoring!B110, if($I$3=9, Scoring!B2, if($I$3=10, Scoring!B74, if($I$3=11, Scoring!B134, Scoring!B50))))))))))) -> Jordan Love (GB) | E14: =if($I$3=1, Scoring!M86, if($I$3=2, Scoring!M26, if($I$3=3, Scoring!M98, if($I$3=4, Scoring!M14, if($I$3=5, Scoring!M62, if($I$3=6, Scoring!M122, if($I$3=7, Scoring!M38, if($I$3=8, Scoring!M110, if($I$3=9, Scoring!M2, if($I$3=10, Scoring!M74, if($I$3=11, Scoring!M134, Scoring!M50))))))))))) -> 26
A15: =if($H$3=1, Scoring!B87, if($H$3=2, Scoring!B27, if($H$3=3, Scoring!B99, if($H$3=4, Scoring!B15, if($H$3=5, Scoring!B63, if($H$3=6, Scoring!B123, if($H$3=7, Scoring!B39, if($H$3=8, Scoring!B111, if($H$3=9, Scoring!B3, if($H$3=10, Scoring!B75, if($H$3=11, Scoring!B135, Scoring!B51))))))))))) -> Zach Charbonnet (Sea) | B15: =if($H$3=1, Scoring!M87, if($H$3=2, Scoring!M27, if($H$3=3, Scoring!M99, if($H$3=4, Scoring!M15, if($H$3=5, Scoring!M63, if($H$3=6, Scoring!M123, if($H$3=7, Scoring!M39, if($H$3=8, Scoring!M111, if($H$3=9, Scoring!M3, if($H$3=10, Scoring!M75, if($H$3=11, Scoring!M135, Scoring!M51))))))))))) -> 6 | D15: =if($I$3=1, Scoring!B87, if($I$3=2, Scoring!B27, if($I$3=3, Scoring!B99, if($I$3=4, Scoring!B15, if($I$3=5, Scoring!B63, if($I$3=6, Scoring!B123, if($I$3=7, Scoring!B39, if($I$3=8, Scoring!B111, if($I$3=9, Scoring!B3, if($I$3=10, Scoring!B75, if($I$3=11, Scoring!B135, Scoring!B51))))))))))) -> Josh Jacobs (GB) | E15: =if($I$3=1, Scoring!M87, if($I$3=2, Scoring!M27, if($I$3=3, Scoring!M99, if($I$3=4, Scoring!M15, if($I$3=5, Scoring!M63, if($I$3=6, Scoring!M123, if($I$3=7, Scoring!M39, if($I$3=8, Scoring!M111, if($I$3=9, Scoring!M3, if($I$3=10, Scoring!M75, if($I$3=11, Scoring!M135, Scoring!M51))))))))))) -> 2
A16: =if($H$3=1, Scoring!B88, if($H$3=2, Scoring!B28, if($H$3=3, Scoring!B100, if($H$3=4, Scoring!B16, if($H$3=5, Scoring!B64, if($H$3=6, Scoring!B124, if($H$3=7, Scoring!B40, if($H$3=8, Scoring!B112, if($H$3=9, Scoring!B4, if($H$3=10, Scoring!B76, if($H$3=11, Scoring!B136, Scoring!B52))))))))))) -> Tyjae Spears (Ten) | B16: =if($H$3=1, Scoring!M88, if($H$3=2, Scoring!M28, if($H$3=3, Scoring!M100, if($H$3=4, Scoring!M16, if($H$3=5, Scoring!M64, if($H$3=6, Scoring!M124, if($H$3=7, Scoring!M40, if($H$3=8, Scoring!M112, if($H$3=9, Scoring!M4, if($H$3=10, Scoring!M76, if($H$3=11, Scoring!M136, Scoring!M52))))))))))) -> 0 | D16: =if($I$3=1, Scoring!B88, if($I$3=2, Scoring!B28, if($I$3=3, Scoring!B100, if($I$3=4, Scoring!B16, if($I$3=5, Scoring!B64, if($I$3=6, Scoring!B124, if($I$3=7, Scoring!B40, if($I$3=8, Scoring!B112, if($I$3=9, Scoring!B4, if($I$3=10, Scoring!B76, if($I$3=11, Scoring!B136, Scoring!B52))))))))))) -> RJ Harvey (Den) | E16: =if($I$3=1, Scoring!M88, if($I$3=2, Scoring!M28, if($I$3=3, Scoring!M100, if($I$3=4, Scoring!M16, if($I$3=5, Scoring!M64, if($I$3=6, Scoring!M124, if($I$3=7, Scoring!M40, if($I$3=8, Scoring!M112, if($I$3=9, Scoring!M4, if($I$3=10, Scoring!M76, if($I$3=11, Scoring!M136, Scoring!M52))))))))))) -> 12
A17: =if($H$3=1, Scoring!B89, if($H$3=2, Scoring!B29, if($H$3=3, Scoring!B101, if($H$3=4, Scoring!B17, if($H$3=5, Scoring!B65, if($H$3=6, Scoring!B125, if($H$3=7, Scoring!B41, if($H$3=8, Scoring!B113, if($H$3=9, Scoring!B5, if($H$3=10, Scoring!B77, if($H$3=11, Scoring!B137, Scoring!B53))))))))))) -> Amon-Ra St. Brown (Det) | B17: =if($H$3=1, Scoring!M89, if($H$3=2, Scoring!M29, if($H$3=3, Scoring!M101, if($H$3=4, Scoring!M17, if($H$3=5, Scoring!M65, if($H$3=6, Scoring!M125, if($H$3=7, Scoring!M41, if($H$3=8, Scoring!M113, if($H$3=9, Scoring!M5, if($H$3=10, Scoring!M77, if($H$3=11, Scoring!M137, Scoring!M53))))))))))) -> 0 | D17: =if($I$3=1, Scoring!B89, if($I$3=2, Scoring!B29, if($I$3=3, Scoring!B101, if($I$3=4, Scoring!B17, if($I$3=5, Scoring!B65, if($I$3=6, Scoring!B125, if($I$3=7, Scoring!B41, if($I$3=8, Scoring!B113, if($I$3=9, Scoring!B5, if($I$3=10, Scoring!B77, if($I$3=11, Scoring!B137, Scoring!B53))))))))))) -> Puka Nacua (LAR) | E17: =if($I$3=1, Scoring!M89, if($I$3=2, Scoring!M29, if($I$3=3, Scoring!M101, if($I$3=4, Scoring!M17, if($I$3=5, Scoring!M65, if($I$3=6, Scoring!M125, if($I$3=7, Scoring!M41, if($I$3=8, Scoring!M113, if($I$3=9, Scoring!M5, if($I$3=10, Scoring!M77, if($I$3=11, Scoring!M137, Scoring!M53))))))))))) -> 0
A18: =if($H$3=1, Scoring!B90, if($H$3=2, Scoring!B30, if($H$3=3, Scoring!B102, if($H$3=4, Scoring!B18, if($H$3=5, Scoring!B66, if($H$3=6, Scoring!B126, if($H$3=7, Scoring!B42, if($H$3=8, Scoring!B114, if($H$3=9, Scoring!B6, if($H$3=10, Scoring!B78, if($H$3=11, Scoring!B138, Scoring!B54))))))))))) -> Marvin Harrison (Arz) | B18: =if($H$3=1, Scoring!M90, if($H$3=2, Scoring!M30, if($H$3=3, Scoring!M102, if($H$3=4, Scoring!M18, if($H$3=5, Scoring!M66, if($H$3=6, Scoring!M126, if($H$3=7, Scoring!M42, if($H$3=8, Scoring!M114, if($H$3=9, Scoring!M6, if($H$3=10, Scoring!M78, if($H$3=11, Scoring!M138, Scoring!M54))))))))))) -> 0 | D18: =if($I$3=1, Scoring!B90, if($I$3=2, Scoring!B30, if($I$3=3, Scoring!B102, if($I$3=4, Scoring!B18, if($I$3=5, Scoring!B66, if($I$3=6, Scoring!B126, if($I$3=7, Scoring!B42, if($I$3=8, Scoring!B114, if($I$3=9, Scoring!B6, if($I$3=10, Scoring!B78, if($I$3=11, Scoring!B138, Scoring!B54))))))))))) -> Davante Adams (LAR) | E18: =if($I$3=1, Scoring!M90, if($I$3=2, Scoring!M30, if($I$3=3, Scoring!M102, if($I$3=4, Scoring!M18, if($I$3=5, Scoring!M66, if($I$3=6, Scoring!M126, if($I$3=7, Scoring!M42, if($I$3=8, Scoring!M114, if($I$3=9, Scoring!M6, if($I$3=10, Scoring!M78, if($I$3=11, Scoring!M138, Scoring!M54))))))))))) -> 12
A19: =if($H$3=1, Scoring!B91, if($H$3=2, Scoring!B31, if($H$3=3, Scoring!B103, if($H$3=4, Scoring!B19, if($H$3=5, Scoring!B67, if($H$3=6, Scoring!B127, if($H$3=7, Scoring!B43, if($H$3=8, Scoring!B115, if($H$3=9, Scoring!B7, if($H$3=10, Scoring!B79, if($H$3=11, Scoring!B139, Scoring!B55))))))))))) -> Brenton Strange (Jax) | B19: =if($H$3=1, Scoring!M91, if($H$3=2, Scoring!M31, if($H$3=3, Scoring!M103, if($H$3=4, Scoring!M19, if($H$3=5, Scoring!M67, if($H$3=6, Scoring!M127, if($H$3=7, Scoring!M43, if($H$3=8, Scoring!M115, if($H$3=9, Scoring!M7, if($H$3=10, Scoring!M79, if($H$3=11, Scoring!M139, Scoring!M55))))))))))) -> 6 | D19: =if($I$3=1, Scoring!B91, if($I$3=2, Scoring!B31, if($I$3=3, Scoring!B103, if($I$3=4, Scoring!B19, if($I$3=5, Scoring!B67, if($I$3=6, Scoring!B127, if($I$3=7, Scoring!B43, if($I$3=8, Scoring!B115, if($I$3=9, Scoring!B7, if($I$3=10, Scoring!B79, if($I$3=11, Scoring!B139, Scoring!B55))))))))))) -> Darren Waller (Mia) | E19: =if($I$3=1, Scoring!M91, if($I$3=2, Scoring!M31, if($I$3=3, Scoring!M103, if($I$3=4, Scoring!M19, if($I$3=5, Scoring!M67, if($I$3=6, Scoring!M127, if($I$3=7, Scoring!M43, if($I$3=8, Scoring!M115, if($I$3=9, Scoring!M7, if($I$3=10, Scoring!M79, if($I$3=11, Scoring!M139, Scoring!M55))))))))))) -> 0
A20: =if($H$3=1, Scoring!B93, if($H$3=2, Scoring!B33, if($H$3=3, Scoring!B105, if($H$3=4, Scoring!B21, if($H$3=5, Scoring!B69, if($H$3=6, Scoring!B129, if($H$3=7, Scoring!B45, if($H$3=8, Scoring!B117, if($H$3=9, Scoring!B9, if($H$3=10, Scoring!B81, if($H$3=11, Scoring!B141, Scoring!B57))))))))))) -> Tyler Loop (Bal) | B20: =if($H$3=1, Scoring!M93, if($H$3=2, Scoring!M33, if($H$3=3, Scoring!M105, if($H$3=4, Scoring!M21, if($H$3=5, Scoring!M69, if($H$3=6, Scoring!M129, if($H$3=7, Scoring!M45, if($H$3=8, Scoring!M117, if($H$3=9, Scoring!M9, if($H$3=10, Scoring!M81, if($H$3=11, Scoring!M141, Scoring!M57))))))))))) -> 2 | D20: =if($I$3=1, Scoring!B93, if($I$3=2, Scoring!B33, if($I$3=3, Scoring!B105, if($I$3=4, Scoring!B21, if($I$3=5, Scoring!B69, if($I$3=6, Scoring!B129, if($I$3=7, Scoring!B45, if($I$3=8, Scoring!B117, if($I$3=9, Scoring!B9, if($I$3=10, Scoring!B81, if($I$3=11, Scoring!B141, Scoring!B57))))))))))) -> Jake Elliott (Phi) | E20: =if($I$3=1, Scoring!M93, if($I$3=2, Scoring!M33, if($I$3=3, Scoring!M105, if($I$3=4, Scoring!M21, if($I$3=5, Scoring!M69, if($I$3=6, Scoring!M129, if($I$3=7, Scoring!M45, if($I$3=8, Scoring!M117, if($I$3=9, Scoring!M9, if($I$3=10, Scoring!M81, if($I$3=11, Scoring!M141, Scoring!M57))))))))))) -> 0
A21: =if($H$3=1, Scoring!B95, if($H$3=2, Scoring!B35, if($H$3=3, Scoring!B107, if($H$3=4, Scoring!B23, if($H$3=5, Scoring!B71, if($H$3=6, Scoring!B131, if($H$3=7, Scoring!B47, if($H$3=8, Scoring!B119, if($H$3=9, Scoring!B11, if($H$3=10, Scoring!B83, if($H$3=11, Scoring!B143, Scoring!B59))))))))))) -> New England | B21: =if($H$3=1, Scoring!M95, if($H$3=2, Scoring!M35, if($H$3=3, Scoring!M107, if($H$3=4, Scoring!M23, if($H$3=5, Scoring!M71, if($H$3=6, Scoring!M131, if($H$3=7, Scoring!M47, if($H$3=8, Scoring!M119, if($H$3=9, Scoring!M11, if($H$3=10, Scoring!M83, if($H$3=11, Scoring!M143, Scoring!M59))))))))))) -> 6 | D21: =if($I$3=1, Scoring!B95, if($I$3=2, Scoring!B35, if($I$3=3, Scoring!B107, if($I$3=4, Scoring!B23, if($I$3=5, Scoring!B71, if($I$3=6, Scoring!B131, if($I$3=7, Scoring!B47, if($I$3=8, Scoring!B119, if($I$3=9, Scoring!B11, if($I$3=10, Scoring!B83, if($I$3=11, Scoring!B143, Scoring!B59))))))))))) -> Denver | E21: =if($I$3=1, Scoring!M95, if($I$3=2, Scoring!M35, if($I$3=3, Scoring!M107, if($I$3=4, Scoring!M23, if($I$3=5, Scoring!M71, if($I$3=6, Scoring!M131, if($I$3=7, Scoring!M47, if($I$3=8, Scoring!M119, if($I$3=9, Scoring!M11, if($I$3=10, Scoring!M83, if($I$3=11, Scoring!M143, Scoring!M59))))))))))) -> 4
A22: =if($H$3=1, Scoring!B97, if($H$3=2, Scoring!B37, if($H$3=3, Scoring!B109, if($H$3=4, Scoring!B25, if($H$3=5, Scoring!B73, if($H$3=6, Scoring!B133, if($H$3=7, Scoring!B49, if($H$3=8, Scoring!B121, if($H$3=9, Scoring!B13, if($H$3=10, Scoring!B85, if($H$3=11, Scoring!B145, Scoring!B61))))))))))) -> Mike Vrabel (NE) | B22: =if($H$3=1, Scoring!M97, if($H$3=2, Scoring!M37, if($H$3=3, Scoring!M109, if($H$3=4, Scoring!M25, if($H$3=5, Scoring!M73, if($H$3=6, Scoring!M133, if($H$3=7, Scoring!M49, if($H$3=8, Scoring!M121, if($H$3=9, Scoring!M13, if($H$3=10, Scoring!M85, if($H$3=11, Scoring!M145, Scoring!M61))))))))))) -> 4 | D22: =if($I$3=1, Scoring!B97, if($I$3=2, Scoring!B37, if($I$3=3, Scoring!B109, if($I$3=4, Scoring!B25, if($I$3=5, Scoring!B73, if($I$3=6, Scoring!B133, if($I$3=7, Scoring!B49, if($I$3=8, Scoring!B121, if($I$3=9, Scoring!B13, if($I$3=10, Scoring!B85, if($I$3=11, Scoring!B145, Scoring!B61))))))))))) -> Sean McVay (LAR) | E22: =if($I$3=1, Scoring!M97, if($I$3=2, Scoring!M37, if($I$3=3, Scoring!M109, if($I$3=4, Scoring!M25, if($I$3=5, Scoring!M73, if($I$3=6, Scoring!M133, if($I$3=7, Scoring!M49, if($I$3=8, Scoring!M121, if($I$3=9, Scoring!M13, if($I$3=10, Scoring!M85, if($I$3=11, Scoring!M145, Scoring!M61))))))))))) -> 0
B23: =sum(B14:B22) -> 35 | E23: =sum(E14:E22) -> 56
A25: =if(H4=1, Scoring!A86, if(H4=2, Scoring!A26, if(H4=3, Scoring!A98, if(H4=4, Scoring!A14, if(H4=5, Scoring!A62, if(H4=6, Scoring!A122, if(H4=7, Scoring!A38, if(H4=8, Scoring!A110, if(H4=9, Scoring!A2, if(H4=10, Scoring!A74, if(H4=11, Scoring!A134, Scoring!A50))))))))))) -> Kevin | D25: =if(I4=1, Scoring!A86, if(I4=2, Scoring!A26, if(I4=3, Scoring!A98, if(I4=4, Scoring!A14, if(I4=5, Scoring!A62, if(I4=6, Scoring!A122, if(I4=7, Scoring!A38, if(I4=8, Scoring!A110, if(I4=9, Scoring!A2, if(I4=10, Scoring!A74, if(I4=11, Scoring!A134, Scoring!A50))))))))))) -> Wes/B
A26: =if($H$4=1, Scoring!B86, if($H$4=2, Scoring!B26, if($H$4=3, Scoring!B98, if($H$4=4, Scoring!B14, if($H$4=5, Scoring!B62, if($H$4=6, Scoring!B122, if($H$4=7, Scoring!B38, if($H$4=8, Scoring!B110, if($H$4=9, Scoring!B2, if($H$4=10, Scoring!B74, if($H$4=11, Scoring!B134, Scoring!B50))))))))))) -> Jalen Hurts (Phi) | B26: =if($H$4=1, Scoring!M86, if($H$4=2, Scoring!M26, if($H$4=3, Scoring!M98, if($H$4=4, Scoring!M14, if($H$4=5, Scoring!M62, if($H$4=6, Scoring!M122, if($H$4=7, Scoring!M38, if($H$4=8, Scoring!M110, if($H$4=9, Scoring!M2, if($H$4=10, Scoring!M74, if($H$4=11, Scoring!M134, Scoring!M50))))))))))) -> 12 | D26: =if($I$4=1, Scoring!B86, if($I$4=2, Scoring!B26, if($I$4=3, Scoring!B98, if($I$4=4, Scoring!B14, if($I$4=5, Scoring!B62, if($I$4=6, Scoring!B122, if($I$4=7, Scoring!B38, if($I$4=8, Scoring!B110, if($I$4=9, Scoring!B2, if($I$4=10, Scoring!B74, if($I$4=11, Scoring!B134, Scoring!B50))))))))))) -> Joe Burrow (Cin) | E26: =if($I$4=1, Scoring!M86, if($I$4=2, Scoring!M26, if($I$4=3, Scoring!M98, if($I$4=4, Scoring!M14, if($I$4=5, Scoring!M62, if($I$4=6, Scoring!M122, if($I$4=7, Scoring!M38, if($I$4=8, Scoring!M110, if($I$4=9, Scoring!M2, if($I$4=10, Scoring!M74, if($I$4=11, Scoring!M134, Scoring!M50))))))))))) -> 15
A27: =if($H$4=1, Scoring!B87, if($H$4=2, Scoring!B27, if($H$4=3, Scoring!B99, if($H$4=4, Scoring!B15, if($H$4=5, Scoring!B63, if($H$4=6, Scoring!B123, if($H$4=7, Scoring!B39, if($H$4=8, Scoring!B111, if($H$4=9, Scoring!B3, if($H$4=10, Scoring!B75, if($H$4=11, Scoring!B135, Scoring!B51))))))))))) -> De'Von Achane (Mia) | B27: =if($H$4=1, Scoring!M87, if($H$4=2, Scoring!M27, if($H$4=3, Scoring!M99, if($H$4=4, Scoring!M15, if($H$4=5, Scoring!M63, if($H$4=6, Scoring!M123, if($H$4=7, Scoring!M39, if($H$4=8, Scoring!M111, if($H$4=9, Scoring!M3, if($H$4=10, Scoring!M75, if($H$4=11, Scoring!M135, Scoring!M51))))))))))) -> 10 | D27: =if($I$4=1, Scoring!B87, if($I$4=2, Scoring!B27, if($I$4=3, Scoring!B99, if($I$4=4, Scoring!B15, if($I$4=5, Scoring!B63, if($I$4=6, Scoring!B123, if($I$4=7, Scoring!B39, if($I$4=8, Scoring!B111, if($I$4=9, Scoring!B3, if($I$4=10, Scoring!B75, if($I$4=11, Scoring!B135, Scoring!B51))))))))))) -> Bijan Robinson (Atl) | E27: =if($I$4=1, Scoring!M87, if($I$4=2, Scoring!M27, if($I$4=3, Scoring!M99, if($I$4=4, Scoring!M15, if($I$4=5, Scoring!M63, if($I$4=6, Scoring!M123, if($I$4=7, Scoring!M39, if($I$4=8, Scoring!M111, if($I$4=9, Scoring!M3, if($I$4=10, Scoring!M75, if($I$4=11, Scoring!M135, Scoring!M51))))))))))) -> 11
A28: =if($H$4=1, Scoring!B88, if($H$4=2, Scoring!B28, if($H$4=3, Scoring!B100, if($H$4=4, Scoring!B16, if($H$4=5, Scoring!B64, if($H$4=6, Scoring!B124, if($H$4=7, Scoring!B40, if($H$4=8, Scoring!B112, if($H$4=9, Scoring!B4, if($H$4=10, Scoring!B76, if($H$4=11, Scoring!B136, Scoring!B52))))))))))) -> Woody Marks (Hou) | B28: =if($H$4=1, Scoring!M88, if($H$4=2, Scoring!M28, if($H$4=3, Scoring!M100, if($H$4=4, Scoring!M16, if($H$4=5, Scoring!M64, if($H$4=6, Scoring!M124, if($H$4=7, Scoring!M40, if($H$4=8, Scoring!M112, if($H$4=9, Scoring!M4, if($H$4=10, Scoring!M76, if($H$4=11, Scoring!M136, Scoring!M52))))))))))) -> 0 | D28: =if($I$4=1, Scoring!B88, if($I$4=2, Scoring!B28, if($I$4=3, Scoring!B100, if($I$4=4, Scoring!B16, if($I$4=5, Scoring!B64, if($I$4=6, Scoring!B124, if($I$4=7, Scoring!B40, if($I$4=8, Scoring!B112, if($I$4=9, Scoring!B4, if($I$4=10, Scoring!B76, if($I$4=11, Scoring!B136, Scoring!B52))))))))))) -> James Cook (Buf) | E28: =if($I$4=1, Scoring!M88, if($I$4=2, Scoring!M28, if($I$4=3, Scoring!M100, if($I$4=4, Scoring!M16, if($I$4=5, Scoring!M64, if($I$4=6, Scoring!M124, if($I$4=7, Scoring!M40, if($I$4=8, Scoring!M112, if($I$4=9, Scoring!M4, if($I$4=10, Scoring!M76, if($I$4=11, Scoring!M136, Scoring!M52))))))))))) -> 4
A29: =if($H$4=1, Scoring!B89, if($H$4=2, Scoring!B29, if($H$4=3, Scoring!B101, if($H$4=4, Scoring!B17, if($H$4=5, Scoring!B65, if($H$4=6, Scoring!B125, if($H$4=7, Scoring!B41, if($H$4=8, Scoring!B113, if($H$4=9, Scoring!B5, if($H$4=10, Scoring!B77, if($H$4=11, Scoring!B137, Scoring!B53))))))))))) -> Deebo Samuel (Was) | B29: =if($H$4=1, Scoring!M89, if($H$4=2, Scoring!M29, if($H$4=3, Scoring!M101, if($H$4=4, Scoring!M17, if($H$4=5, Scoring!M65, if($H$4=6, Scoring!M125, if($H$4=7, Scoring!M41, if($H$4=8, Scoring!M113, if($H$4=9, Scoring!M5, if($H$4=10, Scoring!M77, if($H$4=11, Scoring!M137, Scoring!M53))))))))))) -> 0 | D29: =if($I$4=1, Scoring!B89, if($I$4=2, Scoring!B29, if($I$4=3, Scoring!B101, if($I$4=4, Scoring!B17, if($I$4=5, Scoring!B65, if($I$4=6, Scoring!B125, if($I$4=7, Scoring!B41, if($I$4=8, Scoring!B113, if($I$4=9, Scoring!B5, if($I$4=10, Scoring!B77, if($I$4=11, Scoring!B137, Scoring!B53))))))))))) -> Brian Thomas Jr. (Jax) | E29: =if($I$4=1, Scoring!M89, if($I$4=2, Scoring!M29, if($I$4=3, Scoring!M101, if($I$4=4, Scoring!M17, if($I$4=5, Scoring!M65, if($I$4=6, Scoring!M125, if($I$4=7, Scoring!M41, if($I$4=8, Scoring!M113, if($I$4=9, Scoring!M5, if($I$4=10, Scoring!M77, if($I$4=11, Scoring!M137, Scoring!M53))))))))))) -> 0
A30: =if($H$4=1, Scoring!B90, if($H$4=2, Scoring!B30, if($H$4=3, Scoring!B102, if($H$4=4, Scoring!B18, if($H$4=5, Scoring!B66, if($H$4=6, Scoring!B126, if($H$4=7, Scoring!B42, if($H$4=8, Scoring!B114, if($H$4=9, Scoring!B6, if($H$4=10, Scoring!B78, if($H$4=11, Scoring!B138, Scoring!B54))))))))))) -> Emeka Egbuka (TB) | B30: =if($H$4=1, Scoring!M90, if($H$4=2, Scoring!M30, if($H$4=3, Scoring!M102, if($H$4=4, Scoring!M18, if($H$4=5, Scoring!M66, if($H$4=6, Scoring!M126, if($H$4=7, Scoring!M42, if($H$4=8, Scoring!M114, if($H$4=9, Scoring!M6, if($H$4=10, Scoring!M78, if($H$4=11, Scoring!M138, Scoring!M54))))))))))) -> 0 | D30: =if($I$4=1, Scoring!B90, if($I$4=2, Scoring!B30, if($I$4=3, Scoring!B102, if($I$4=4, Scoring!B18, if($I$4=5, Scoring!B66, if($I$4=6, Scoring!B126, if($I$4=7, Scoring!B42, if($I$4=8, Scoring!B114, if($I$4=9, Scoring!B6, if($I$4=10, Scoring!B78, if($I$4=11, Scoring!B138, Scoring!B54))))))))))) -> A.J. Brown (PHI) | E30: =if($I$4=1, Scoring!M90, if($I$4=2, Scoring!M30, if($I$4=3, Scoring!M102, if($I$4=4, Scoring!M18, if($I$4=5, Scoring!M66, if($I$4=6, Scoring!M126, if($I$4=7, Scoring!M42, if($I$4=8, Scoring!M114, if($I$4=9, Scoring!M6, if($I$4=10, Scoring!M78, if($I$4=11, Scoring!M138, Scoring!M54))))))))))) -> 16
A31: =if($H$4=1, Scoring!B91, if($H$4=2, Scoring!B31, if($H$4=3, Scoring!B103, if($H$4=4, Scoring!B19, if($H$4=5, Scoring!B67, if($H$4=6, Scoring!B127, if($H$4=7, Scoring!B43, if($H$4=8, Scoring!B115, if($H$4=9, Scoring!B7, if($H$4=10, Scoring!B79, if($H$4=11, Scoring!B139, Scoring!B55))))))))))) -> Travis Kelce (KC) | B31: =if($H$4=1, Scoring!M91, if($H$4=2, Scoring!M31, if($H$4=3, Scoring!M103, if($H$4=4, Scoring!M19, if($H$4=5, Scoring!M67, if($H$4=6, Scoring!M127, if($H$4=7, Scoring!M43, if($H$4=8, Scoring!M115, if($H$4=9, Scoring!M7, if($H$4=10, Scoring!M79, if($H$4=11, Scoring!M139, Scoring!M55))))))))))) -> 6 | D31: =if($I$4=1, Scoring!B91, if($I$4=2, Scoring!B31, if($I$4=3, Scoring!B103, if($I$4=4, Scoring!B19, if($I$4=5, Scoring!B67, if($I$4=6, Scoring!B127, if($I$4=7, Scoring!B43, if($I$4=8, Scoring!B115, if($I$4=9, Scoring!B7, if($I$4=10, Scoring!B79, if($I$4=11, Scoring!B139, Scoring!B55))))))))))) -> Brock Bowers (LV) | E31: =if($I$4=1, Scoring!M91, if($I$4=2, Scoring!M31, if($I$4=3, Scoring!M103, if($I$4=4, Scoring!M19, if($I$4=5, Scoring!M67, if($I$4=6, Scoring!M127, if($I$4=7, Scoring!M43, if($I$4=8, Scoring!M115, if($I$4=9, Scoring!M7, if($I$4=10, Scoring!M79, if($I$4=11, Scoring!M139, Scoring!M55))))))))))) -> 14
A32: =if($H$4=1, Scoring!B93, if($H$4=2, Scoring!B33, if($H$4=3, Scoring!B105, if($H$4=4, Scoring!B21, if($H$4=5, Scoring!B69, if($H$4=6, Scoring!B129, if($H$4=7, Scoring!B45, if($H$4=8, Scoring!B117, if($H$4=9, Scoring!B9, if($H$4=10, Scoring!B81, if($H$4=11, Scoring!B141, Scoring!B57))))))))))) -> Chris Boswell (Pit) | B32: =if($H$4=1, Scoring!M93, if($H$4=2, Scoring!M33, if($H$4=3, Scoring!M105, if($H$4=4, Scoring!M21, if($H$4=5, Scoring!M69, if($H$4=6, Scoring!M129, if($H$4=7, Scoring!M45, if($H$4=8, Scoring!M117, if($H$4=9, Scoring!M9, if($H$4=10, Scoring!M81, if($H$4=11, Scoring!M141, Scoring!M57))))))))))) -> 1 | D32: =if($I$4=1, Scoring!B93, if($I$4=2, Scoring!B33, if($I$4=3, Scoring!B105, if($I$4=4, Scoring!B21, if($I$4=5, Scoring!B69, if($I$4=6, Scoring!B129, if($I$4=7, Scoring!B45, if($I$4=8, Scoring!B117, if($I$4=9, Scoring!B9, if($I$4=10, Scoring!B81, if($I$4=11, Scoring!B141, Scoring!B57))))))))))) -> Jake Bates (Det) | E32: =if($I$4=1, Scoring!M93, if($I$4=2, Scoring!M33, if($I$4=3, Scoring!M105, if($I$4=4, Scoring!M21, if($I$4=5, Scoring!M69, if($I$4=6, Scoring!M129, if($I$4=7, Scoring!M45, if($I$4=8, Scoring!M117, if($I$4=9, Scoring!M9, if($I$4=10, Scoring!M81, if($I$4=11, Scoring!M141, Scoring!M57))))))))))) -> 5
A33: =if($H$4=1, Scoring!B95, if($H$4=2, Scoring!B35, if($H$4=3, Scoring!B107, if($H$4=4, Scoring!B23, if($H$4=5, Scoring!B71, if($H$4=6, Scoring!B131, if($H$4=7, Scoring!B47, if($H$4=8, Scoring!B119, if($H$4=9, Scoring!B11, if($H$4=10, Scoring!B83, if($H$4=11, Scoring!B143, Scoring!B59))))))))))) -> LA Rams | B33: =if($H$4=1, Scoring!M95, if($H$4=2, Scoring!M35, if($H$4=3, Scoring!M107, if($H$4=4, Scoring!M23, if($H$4=5, Scoring!M71, if($H$4=6, Scoring!M131, if($H$4=7, Scoring!M47, if($H$4=8, Scoring!M119, if($H$4=9, Scoring!M11, if($H$4=10, Scoring!M83, if($H$4=11, Scoring!M143, Scoring!M59))))))))))) -> 0 | D33: =if($I$4=1, Scoring!B95, if($I$4=2, Scoring!B35, if($I$4=3, Scoring!B107, if($I$4=4, Scoring!B23, if($I$4=5, Scoring!B71, if($I$4=6, Scoring!B131, if($I$4=7, Scoring!B47, if($I$4=8, Scoring!B119, if($I$4=9, Scoring!B11, if($I$4=10, Scoring!B83, if($I$4=11, Scoring!B143, Scoring!B59))))))))))) -> Indianapolis | E33: =if($I$4=1, Scoring!M95, if($I$4=2, Scoring!M35, if($I$4=3, Scoring!M107, if($I$4=4, Scoring!M23, if($I$4=5, Scoring!M71, if($I$4=6, Scoring!M131, if($I$4=7, Scoring!M47, if($I$4=8, Scoring!M119, if($I$4=9, Scoring!M11, if($I$4=10, Scoring!M83, if($I$4=11, Scoring!M143, Scoring!M59))))))))))) -> 4
A34: =if($H$4=1, Scoring!B97, if($H$4=2, Scoring!B37, if($H$4=3, Scoring!B109, if($H$4=4, Scoring!B25, if($H$4=5, Scoring!B73, if($H$4=6, Scoring!B133, if($H$4=7, Scoring!B49, if($H$4=8, Scoring!B121, if($H$4=9, Scoring!B13, if($H$4=10, Scoring!B85, if($H$4=11, Scoring!B145, Scoring!B61))))))))))) -> Kyle Shanahan (SF) | B34: =if($H$4=1, Scoring!M97, if($H$4=2, Scoring!M37, if($H$4=3, Scoring!M109, if($H$4=4, Scoring!M25, if($H$4=5, Scoring!M73, if($H$4=6, Scoring!M133, if($H$4=7, Scoring!M49, if($H$4=8, Scoring!M121, if($H$4=9, Scoring!M13, if($H$4=10, Scoring!M85, if($H$4=11, Scoring!M145, Scoring!M61))))))))))) -> 5 | D34: =if($I$4=1, Scoring!B97, if($I$4=2, Scoring!B37, if($I$4=3, Scoring!B109, if($I$4=4, Scoring!B25, if($I$4=5, Scoring!B73, if($I$4=6, Scoring!B133, if($I$4=7, Scoring!B49, if($I$4=8, Scoring!B121, if($I$4=9, Scoring!B13, if($I$4=10, Scoring!B85, if($I$4=11, Scoring!B145, Scoring!B61))))))))))) -> Liam Coen (Jax) | E34: =if($I$4=1, Scoring!M97, if($I$4=2, Scoring!M37, if($I$4=3, Scoring!M109, if($I$4=4, Scoring!M25, if($I$4=5, Scoring!M73, if($I$4=6, Scoring!M133, if($I$4=7, Scoring!M49, if($I$4=8, Scoring!M121, if($I$4=9, Scoring!M13, if($I$4=10, Scoring!M85, if($I$4=11, Scoring!M145, Scoring!M61))))))))))) -> 5
B35: =sum(B26:B34) -> 34 | E35: =sum(E26:E34) -> 74
A37: =if(H5=1, Scoring!A86, if(H5=2, Scoring!A26, if(H5=3, Scoring!A98, if(H5=4, Scoring!A14, if(H5=5, Scoring!A62, if(H5=6, Scoring!A122, if(H5=7, Scoring!A38, if(H5=8, Scoring!A110, if(H5=9, Scoring!A2, if(H5=10, Scoring!A74, if(H5=11, Scoring!A134, Scoring!A50))))))))))) -> Eric/J | D37: =if(I5=1, Scoring!A86, if(I5=2, Scoring!A26, if(I5=3, Scoring!A98, if(I5=4, Scoring!A14, if(I5=5, Scoring!A62, if(I5=6, Scoring!A122, if(I5=7, Scoring!A38, if(I5=8, Scoring!A110, if(I5=9, Scoring!A2, if(I5=10, Scoring!A74, if(I5=11, Scoring!A134, Scoring!A50))))))))))) -> Andrew
A38: =if($H$5=1, Scoring!B86, if($H$5=2, Scoring!B26, if($H$5=3, Scoring!B98, if($H$5=4, Scoring!B14, if($H$5=5, Scoring!B62, if($H$5=6, Scoring!B122, if($H$5=7, Scoring!B38, if($H$5=8, Scoring!B110, if($H$5=9, Scoring!B2, if($H$5=10, Scoring!B74, if($H$5=11, Scoring!B134, Scoring!B50))))))))))) -> Justin Herbert (LAC) | B38: =if($H$5=1, Scoring!M86, if($H$5=2, Scoring!M26, if($H$5=3, Scoring!M98, if($H$5=4, Scoring!M14, if($H$5=5, Scoring!M62, if($H$5=6, Scoring!M122, if($H$5=7, Scoring!M38, if($H$5=8, Scoring!M110, if($H$5=9, Scoring!M2, if($H$5=10, Scoring!M74, if($H$5=11, Scoring!M134, Scoring!M50))))))))))) -> 11 | D38: =if($I$5=1, Scoring!B86, if($I$5=2, Scoring!B26, if($I$5=3, Scoring!B98, if($I$5=4, Scoring!B14, if($I$5=5, Scoring!B62, if($I$5=6, Scoring!B122, if($I$5=7, Scoring!B38, if($I$5=8, Scoring!B110, if($I$5=9, Scoring!B2, if($I$5=10, Scoring!B74, if($I$5=11, Scoring!B134, Scoring!B50))))))))))) -> Trevor Lawrence (Jax) | E38: =if($I$5=1, Scoring!M86, if($I$5=2, Scoring!M26, if($I$5=3, Scoring!M98, if($I$5=4, Scoring!M14, if($I$5=5, Scoring!M62, if($I$5=6, Scoring!M122, if($I$5=7, Scoring!M38, if($I$5=8, Scoring!M110, if($I$5=9, Scoring!M2, if($I$5=10, Scoring!M74, if($I$5=11, Scoring!M134, Scoring!M50))))))))))) -> 16
A39: =if($H$5=1, Scoring!B87, if($H$5=2, Scoring!B27, if($H$5=3, Scoring!B99, if($H$5=4, Scoring!B15, if($H$5=5, Scoring!B63, if($H$5=6, Scoring!B123, if($H$5=7, Scoring!B39, if($H$5=8, Scoring!B111, if($H$5=9, Scoring!B3, if($H$5=10, Scoring!B75, if($H$5=11, Scoring!B135, Scoring!B51))))))))))) -> TreVeyon Henderson (NE) | B39: =if($H$5=1, Scoring!M87, if($H$5=2, Scoring!M27, if($H$5=3, Scoring!M99, if($H$5=4, Scoring!M15, if($H$5=5, Scoring!M63, if($H$5=6, Scoring!M123, if($H$5=7, Scoring!M39, if($H$5=8, Scoring!M111, if($H$5=9, Scoring!M3, if($H$5=10, Scoring!M75, if($H$5=11, Scoring!M135, Scoring!M51))))))))))) -> 0 | D39: =if($I$5=1, Scoring!B87, if($I$5=2, Scoring!B27, if($I$5=3, Scoring!B99, if($I$5=4, Scoring!B15, if($I$5=5, Scoring!B63, if($I$5=6, Scoring!B123, if($I$5=7, Scoring!B39, if($I$5=8, Scoring!B111, if($I$5=9, Scoring!B3, if($I$5=10, Scoring!B75, if($I$5=11, Scoring!B135, Scoring!B51))))))))))) -> Kenneth Walker III (Sea) | E39: =if($I$5=1, Scoring!M87, if($I$5=2, Scoring!M27, if($I$5=3, Scoring!M99, if($I$5=4, Scoring!M15, if($I$5=5, Scoring!M63, if($I$5=6, Scoring!M123, if($I$5=7, Scoring!M39, if($I$5=8, Scoring!M111, if($I$5=9, Scoring!M3, if($I$5=10, Scoring!M75, if($I$5=11, Scoring!M135, Scoring!M51))))))))))) -> 0
A40: =if($H$5=1, Scoring!B88, if($H$5=2, Scoring!B28, if($H$5=3, Scoring!B100, if($H$5=4, Scoring!B16, if($H$5=5, Scoring!B64, if($H$5=6, Scoring!B124, if($H$5=7, Scoring!B40, if($H$5=8, Scoring!B112, if($H$5=9, Scoring!B4, if($H$5=10, Scoring!B76, if($H$5=11, Scoring!B136, Scoring!B52))))))))))) -> Javonte Williams (Dal) | B40: =if($H$5=1, Scoring!M88, if($H$5=2, Scoring!M28, if($H$5=3, Scoring!M100, if($H$5=4, Scoring!M16, if($H$5=5, Scoring!M64, if($H$5=6, Scoring!M124, if($H$5=7, Scoring!M40, if($H$5=8, Scoring!M112, if($H$5=9, Scoring!M4, if($H$5=10, Scoring!M76, if($H$5=11, Scoring!M136, Scoring!M52))))))))))) -> 6 | D40: =if($I$5=1, Scoring!B88, if($I$5=2, Scoring!B28, if($I$5=3, Scoring!B100, if($I$5=4, Scoring!B16, if($I$5=5, Scoring!B64, if($I$5=6, Scoring!B124, if($I$5=7, Scoring!B40, if($I$5=8, Scoring!B112, if($I$5=9, Scoring!B4, if($I$5=10, Scoring!B76, if($I$5=11, Scoring!B136, Scoring!B52))))))))))) -> David Montgomery (Det) | E40: =if($I$5=1, Scoring!M88, if($I$5=2, Scoring!M28, if($I$5=3, Scoring!M100, if($I$5=4, Scoring!M16, if($I$5=5, Scoring!M64, if($I$5=6, Scoring!M124, if($I$5=7, Scoring!M40, if($I$5=8, Scoring!M112, if($I$5=9, Scoring!M4, if($I$5=10, Scoring!M76, if($I$5=11, Scoring!M136, Scoring!M52))))))))))) -> 6
