Workbook

Sheet Playoffs
B1: 1st | C1: 2nd | D1: 3rd | E1: 4th | F1: Oakland | G1: Toilet
B2: Place | C2: Place | D2: Place | E2: Place | F2: Bowl Score | G2: Bowl Score | H2: Jamboree | I2: Comments | K2: # of Teams
A4: 1988 | B4: Bill | C4: Steve M. | D4: Eric H. | E4: Kreg | F4: 45-34 | G4: 64-62 | I4: Bill's first championship in Oakland Bowl I. | K4: 8
A5: 1989 | B5: Chris | C5: Eric H. | D5: Eric S. | E5: Nan/Kemp | F5: 66-42 | G5: 52-37 | I5: Chris' first championship. First team to go from worst to first. | J5: Expanded from 8 to 10 teams. | K5: 10
A6: 1990 | B6: Bill | C6: Chris | D6: Kreg | E6: John | F6: 25-22 | G6: 33-31 | I6: Bill's second championship with only 25 Oakland Bowl pts. | K6: 10
A7: 1991 | B7: Steve M. | C7: John | D7: Chris | E7: Nan/Kemp | F7: 74-17 | G7: 57-48 | I7: Steve M's first championship. | K7: 10
A8: 1992 | B8: Steve L. | C8: Steve M. | D8: Kirk | E8: Bill | F8: 38-35 | G8: 34-30 | I8: Steve L's first championship. | K8: 10
A9: 1993 | B9: Bill | C9: Steve L. | D9: John | E9: Eric H. | F9: 67-41 | G9: 69-50 | I9: Bill's third championship. | K9: 10
A10: 1994 | B10: Bill | C10: John | D10: Eric H. | E10: Steve L. | F10: 68-47 | G10: 68-35 | I10: Bill's fourth championship and first repeat. | K10: 10
A11: 1995 | B11: Chris | C11: Steve L. | D11: Kemp | E11: John | F11: 67-36 | G11: 85-58 | I11: Chris' second championship. | K11: 10
A12: 1996 | B12: Steve/J | C12: Eric S. | D12: John | E12: Chris | F12: 39-16 | G12: 57-57 | I12: Steve/J win despite 6-8-1 season record. | K12: 10
A13: 1997 | B13: Kemp | C13: Bill | D13: Chris | E13: Kreg/J | F13: 27-24 | G13: 77-60 | I13: Kemp's first championship at 16 years of age. | K13: 10
A14: 1998 | B14: Eric S. | C14: John | D14: Steve L. | E14: Eric H. | F14: 47-41 | G14: 46-32 | I14: Eric S's first championship. | K14: 10
A15: 1999 | B15: Eric S. | C15: Steve L. | D15: Steve/J | E15: Kemp/Rams | F15: 86-51 | G15: 54-43 | I15: Eric S. wins repeat championships. | K15: 10
A16: 2000 | B16: John | C16: Steve/J | D16: Kemp/Rams | E16: Steve L. | F16: 84-55 | G16: 90-58 | I16: John's first championship. | K16: 10
A17: 2001 | B17: Kemp/Rams | C17: John | D17: Kirk | E17: Steve L. | F17: 65-59 | G17: 44-41 | I17: Kemp/Ramsey's first team championship. Kemp's second. | J17: Eliminated 2 division format. | K17: 10
A18: 2002 | B18: Adam/Nick | C18: Greg | D18: Eric S. | E18: John | F18: 28-28* | G18: 66-54 | H18: Kemp/Rams (115) | I18: * Adam wins on better record w/ championship in first year. | J18: Expanded from 10 to 12 teams. | K18: 12
A19: 2003 | B19: Kirk | C19: Steve/Wes | D19: John | E19: Steve L. | F19: 55-46 | G19: 52-23 | H19: Jarrett (139) | I19: Kirk's first championship. | K19: 12
A20: 2004 | B20: Kreg | C20: John | D20: Adam/Nick/Bill | E20: Steve L. | F20: 69-57 | G20: 48-36 | H20: Eric H. (165) | I20: Kreg's first championship. John's fifth consecutive playoff berth. | K20: 12
A21: 2005 | B21: Jarrett | C21: Eric/Bret/Joe | D21: Kirk | E21: Steve/Wes | F21: 48-34 | G21: 54-35 | H21: Eric S. (132) | I21: Jarrett's first championship. | K21: 12
A22: 2006 | B22: Kirk | C22: John | D22: Kevin | E22: Jarrett | F22: 52-52* | G22: 58-54 | H22: Kemp (147) | I22: * Kirk wins on better record because of John's roster snafu. | J22: Changed from 15 to 14 game season. | K22: 12
A23: 2007 | B23: Eric S. | C23: Kevin | D23: Mike | E23: Kirk | F23: 55-23 | G23: 67-48 | H23: Jarrett (121) | I23: Eric S's third championship with Sean Taylor magic. | K23: 12
A24: 2008 | B24: Steve L. | C24: Greg | D24: John | E24: Jarrett | F24: 67-28 | G24: 67-30 | H24: Eric S. (109) | I24: Steve L's second championship. | K24: 12
A25: 2009 | B25: Steve L. | C25: Bill | D25: Greg | E25: John | F25: 57-57* | G25: 62-31 | H25: Jarrett (129) | I25: *Steve L wins repeat championship on better record for third ring. | J25: Changed to W-L & Top-6 format. | K25: 12
A26: 2010 | B26: Kirk/David | C26: John | D26: Steve L. | E26: Kevin | F26: 62-43 | G26: 37-26 | H26: Jarrett (145) | I26: Kirk/David's third championship. John 1-7 in Oakland Bowl. Ouch! | K26: 12
A27: 2011 | B27: Bill/Jill | C27: Kirk/David | D27: Greg | E27: Steve L. | F27: 89-48 | G27: 47-36 | H27: Kevin (124) | I27: Bill gets "one for the thumb." Steve Lam loses to Bill on late roster in round 1. | K27: 12
A28: 2012 | B28: Kevin | C28: Kirk/David | D28: John | E28: Steve/Wes | F28: 67-62 | G28: 44-44 | H28: Adam (147) | I28: Kevin's first championship. Kirk/David's third Oakland Bowl in a row. | K28: 12
A29: 2013 | B29: Jarrett | C29: Steve L. | D29: Adam | E29: Steve/Wes | F29: 48-42 | G29: 42-39 | H29: Greg (124) | I29: Jarrett's second solo championship. Steve/Wes' fourth straight playoff loss. | J29: Changed scoring system | K29: 12
A30: 2014 | B30: Steve L. | C30: Kirk/David | D30: Steve/Wes | E30: John | F30: 57-31 | G30: 62-46 | H30: Greg/Griff (111) | I30: Steve L's fourth championship. | K30: 12
A31: 2015 | B31: Steve L. | C31: Adam | D31: Greg/Griffin | E31: Kirk/David | F31: 65-32 | G31: 41-38 | H31: Jarrett (126) | I31: Steve L. wins second repeat championships and gets "one for the thumb." | K31: 12
A32: 2016 | B32: Kemp/Ad/Miles | C32: Steve L. | D32: Steve/Wes | E32: Eric/Jeff | F32: 61-33 | G32: 76-49 | H32: Bill/Jill (115) | I32: Kemp recruits the third generation (Adelese and Miles) to win third title. | K32: 12
A33: 2017 | B33: Kirk/David | C33: Steve L./Wes | D33: Greg/Griffin | E33: Andrew | F33: 52-51 | G33: 59-25 | H33: Eric/Jeff (115) | I33: Kirk/David's fourth championship. Steve L.'s fifth straight Oakland Bowl. | J33: Added combined yardage scoring | K33: 12
A34: 2018 | B34: Adam | C34: Jarrett/Matt | D34: Steve L. | E34: Kirk/David | F34: 63-35 | G34: 69-58 | H34: Steve M. (117) | I34: Adam's second championship. Second team to go from worst to first. | K34: 12
A35: 2019 | B35: Andrew | C35: Kirk/David | D35: Jarrett/Matt | E35: Steve L. | F35: 76-61 | G35: 66-50 | H35: Adam (141) | I35: Andrew wins first championship in his 11th year behind Jackson & McCaffrey. | K35: 12
A36: 2020 | B36: Kemp/Ad/Miles | C36: Jarrett/Matt | D36: Kirk/David | E36: Steve M. | F36: 67-57 | G36: 73-58 | H36: Kevin (125) | I36: Kemp/Ad/Miles add fourth championship with 4-0 record in the Oakland Bowl. | K36: 12
A37: 2021 | B37: Kemp/Ad/Miles | C37: Greg/Griffin | D37: Kevin | E37: Eric/Jeff | F37: 41-40 | G37: 60-XX | H37: Wes/Bill (149) | I37: Kemp/A/M get "one for the thumb" with repeat and 5-0 record in the Oakland Bowl. | K37: 12
A38: 2022 | B38: Jarrett/Matt & Wes | C38: Jarrett/Matt & Wes | D38: John & Kemp/A/M | E38: John & Kemp/A/M | F38: 53-45 | G38: 23-10 | H38: Kirk/David (122) | I38: Jarrett/Matt and Wes declare historic tie when Bills Bengals game gets cancelled. | K38: 12
A39: 2023 | B39: Kemp/Ad/Miles | C39: Greg/Griffin | D39: Jarrett/Matt | E39: Kevin | F39: 43-31 | G39: 56-47 | H39: John (120) | I39: Kemp/A/M win sixth championship and remain undefeated in the Oakland Bowl!!! | K39: 12
A40: 2024 | B40: Kemp/Ad/Miles | C40: Wes | D40: John | E40: Jarrett/Matt | F40: 88-57 | G40: 59-51 | H40: Steve L. (157) | I40: Kemp/A/M win seventh championship and 4 of last 5 Oakland Bowls!!!! | K40: 12
B42: 1st | C42: 2nd | D42: 3rd | E42: 4th | F42: Playoff | G42: # of | H42: % of | J42: Team Seasons Total | K42: =SUM(K4:K41) -> 414
...

Sheet W-L Records
C1: Steve M. | H1: John | M1: Steve L. | R1: Eric/Jeff | W1: Kemp | AB1: Kirk/David | AG1: Greg/Griffin | AL1: Adam | AQ1: Jarrett/Matt | AV1: Kevin | BA1: Bill | BF1: Andrew | BK1: Wes | BP1: Danny/Joey | BU1: Mike | BZ1: Eric/Bret/Joe | CE1: Kreg | CJ1: Chris | CO1: Harold | CT1: Mark | CZ1: # | DA1: Pts | DB1: Avg | DE1: GmA
C2: W | D2: L | E2: T | F2: T6 | G2: Pts | H2: W | I2: L | J2: T | K2: T6 | L2: Pts | M2: W | N2: L | O2: T | P2: T6 | Q2: Pts | R2: W | S2: L | T2: T | U2: T6 | V2: Pts | W2: W | X2: L | Y2: T | Z2: T6 | AA2: Pts | AB2: W | AC2: L | AD2: T | AE2: T6 | AF2: Pts | AG2: W | AH2: L | AI2: T | AJ2: T6 | AK2: Pts | AL2: W | AM2: L | AN2: T | AO2: T6 | AP2: Pts | AQ2: W | AR2: L | AS2: T | AT2: T6 | AU2: Pts | AV2: W | AW2: L | AX2: T | AY2: T6 | AZ2: Pts | BA2: W | BB2: L | BC2: T | BD2: T6 | BE2: Pts | BF2: W | BG2: L | BH2: T | BI2: T6 | BJ2: Pts | BK2: W | BL2: L | BM2: T | BN2: T6 | BO2: Pts | BP2: W | BQ2: L | BR2: T | BS2: T6 | BT2: Pts | BU2: W | BV2: L | BW2: T | BX2: T6 | BY2: Pts | BZ2: W | CA2: L | CB2: T | CC2: T6 | CD2: Pts | CE2: W | CF2: L | CG2: T | CH2: T6 | CI2: Pts | CJ2: W | CK2: L | CL2: T | CM2: T6 | CN2: Pts | CO2: W | CP2: L | CQ2: T | CR2: T6 | CS2: Pts | CT2: W | CU2: L | CV2: T | CW2: T6 | CX2: Pts
A3: 1988 | C3: 9 | D3: 5 | E3: 0 | G3: 508 | H3: 5 | I3: 8 | J3: 1 | L3: 646 | M3: 6 | N3: 7 | O3: 1 | Q3: 462 | BA3: 7 | BB3: 7 | BC3: 0 | BE3: 599 | BZ3: 12 | CA3: 2 | CB3: 0 | CD3: 768 | CE3: 8 | CF3: 5 | CG3: 1 | CI3: 477 | CJ3: 3 | CK3: 10 | CL3: 1 | CN3: 436 | CT3: 4 | CU3: 10 | CV3: 0 | CX3: 482 | CZ3: 8 | DA3: =+G3+L3+Q3+V3+AA3+AF3+AK3+AP3+AU3+AZ3+BE3+BJ3+BO3+BT3+BY3+CD3+CI3+CN3+CS3+CX3 -> 4378 | DB3: =+DA3/CZ3 -> 547.25
A4: 1989 | C4: 5 | D4: 9 | E4: 0 | G4: 565 | H4: 7 | I4: 7 | J4: 0 | L4: 644 | M4: 5 | N4: 9 | O4: 0 | Q4: 565 | R4: 8 | S4: 6 | T4: 0 | V4: 593 | W4: 8 | X4: 6 | Y4: 0 | AA4: 647 | BA4: 5 | BB4: 9 | BC4: 0 | BE4: 591 | BZ4: 9 | CA4: 5 | CB4: 0 | CD4: 722 | CE4: 6 | CF4: 8 | CG4: 0 | CI4: 567 | CJ4: 9 | CK4: 5 | CL4: 0 | CN4: 707 | CO4: 8 | CP4: 6 | CQ4: 0 | CS4: 565 | CZ4: 10 | DA4: =+G4+L4+Q4+V4+AA4+AF4+AK4+AP4+AU4+AZ4+BE4+BJ4+BO4+BT4+BY4+CD4+CI4+CN4+CS4+CX4 -> 6166 | DB4: =+DA4/CZ4 -> 616.6
A5: 1990 | C5: 8 | D5: 7 | E5: 0 | G5: 704 | H5: 10 | I5: 4 | J5: 1 | L5: 741 | M5: 8 | N5: 7 | O5: 0 | Q5: 583 | R5: 6 | S5: 9 | T5: 0 | V5: 566 | W5: 7 | X5: 7 | Y5: 1 | AA5: 604 | BA5: 10 | BB5: 5 | BC5: 0 | BE5: 708 | BZ5: 6 | CA5: 9 | CB5: 0 | CD5: 529 | CE5: 9 | CF5: 6 | CG5: 0 | CI5: 689 | CJ5: 7 | CK5: 6 | CL5: 2 | CN5: 716 | CO5: 2 | CP5: 13 | CQ5: 0 | CS5: 425 | CZ5: 10 | DA5: =+G5+L5+Q5+V5+AA5+AF5+AK5+AP5+AU5+AZ5+BE5+BJ5+BO5+BT5+BY5+CD5+CI5+CN5+CS5+CX5 -> 6265 | DB5: =+DA5/CZ5 -> 626.5
A6: 1991 | C6: 9 | D6: 5 | E6: 1 | G6: 763 | H6: 9 | I6: 6 | J6: 0 | L6: 619 | M6: 8 | N6: 7 | O6: 0 | Q6: 635 | R6: 7 | S6: 8 | T6: 0 | V6: 581 | W6: 10 | X6: 4 | Y6: 1 | AA6: 586 | AB6: 3 | AC6: 12 | AD6: 0 | AF6: 450 | BA6: 8 | BB6: 7 | BC6: 0 | BE6: 644 | BZ6: 7 | CA6: 8 | CB6: 0 | CD6: 555 | CE6: 5 | CF6: 10 | CG6: 0 | CI6: 533 | CJ6: 8 | CK6: 7 | CL6: 0 | CN6: 682 | CZ6: 10 | DA6: =+G6+L6+Q6+V6+AA6+AF6+AK6+AP6+AU6+AZ6+BE6+BJ6+BO6+BT6+BY6+CD6+CI6+CN6+CS6+CX6 -> 6048 | DB6: =+DA6/CZ6 -> 604.8
A7: 1992 | C7: 9 | D7: 6 | E7: 0 | G7: 670 | H7: 7 | I7: 7 | J7: 1 | L7: 743 | M7: 12 | N7: 2 | O7: 1 | Q7: 757 | R7: 7 | S7: 8 | T7: 0 | V7: 548 | W7: 7 | X7: 8 | Y7: 0 | AA7: 638 | AB7: 8 | AC7: 7 | AD7: 0 | AF7: 669 | BA7: 8 | BB7: 7 | BC7: 0 | BE7: 713 | BZ7: 7 | CA7: 8 | CB7: 0 | CD7: 640 | CE7: 6 | CF7: 9 | CG7: 0 | CI7: 539 | CJ7: 3 | CK7: 12 | CL7: 0 | CN7: 559 | CZ7: 10 | DA7: =+G7+L7+Q7+V7+AA7+AF7+AK7+AP7+AU7+AZ7+BE7+BJ7+BO7+BT7+BY7+CD7+CI7+CN7+CS7+CX7 -> 6476 | DB7: =+DA7/CZ7 -> 647.6
A8: 1993 | C8: 6 | D8: 9 | E8: 1 | G8: 647 | H8: 10 | I8: 5 | J8: 1 | L8: 705 | M8: 9 | N8: 7 | O8: 0 | Q8: 745 | R8: 8 | S8: 8 | T8: 0 | V8: 616 | W8: 7 | X8: 9 | Y8: 0 | AA8: 621 | AB8: 5 | AC8: 11 | AD8: 0 | AF8: 534 | BA8: 9 | BB8: 7 | BC8: 0 | BE8: 629 | BZ8: 10 | CA8: 6 | CB8: 0 | CD8: 612 | CE8: 6 | CF8: 10 | CG8: 0 | CI8: 532 | CJ8: 9 | CK8: 7 | CL8: 0 | CN8: 670 | CZ8: 10 | DA8: =+G8+L8+Q8+V8+AA8+AF8+AK8+AP8+AU8+AZ8+BE8+BJ8+BO8+BT8+BY8+CD8+CI8+CN8+CS8+CX8 -> 6311 | DB8: =+DA8/CZ8 -> 631.1
A9: 1994 | C9: 5 | D9: 10 | E9: 0 | G9: 636 | H9: 10 | I9: 5 | J9: 0 | L9: 781 | M9: 11 | N9: 4 | O9: 0 | Q9: 943 | R9: 4 | S9: 11 | T9: 0 | V9: 632 | W9: 2 | X9: 10 | Y9: 1 | AA9: 549 | AB9: 8 | AC9: 7 | AD9: 0 | AF9: 622 | BA9: 8 | BB9: 7 | BC9: 0 | BE9: 734 | BZ9: 11 | CA9: 4 | CB9: 0 | CD9: 654 | CE9: 5 | CF9: 10 | CG9: 0 | CI9: 572 | CJ9: 10 | CK9: 4 | CL9: 1 | CN9: 750 | CZ9: 10 | DA9: =+G9+L9+Q9+V9+AA9+AF9+AK9+AP9+AU9+AZ9+BE9+BJ9+BO9+BT9+BY9+CD9+CI9+CN9+CS9+CX9 -> 6873 | DB9: =+DA9/CZ9 -> 687.3
A10: 1995 | C10: 7 | D10: 8 | E10: 0 | G10: 756 | H10: 10 | I10: 5 | J10: 0 | L10: 969 | M10: 8 | N10: 7 | O10: 0 | Q10: 802 | R10: 9 | S10: 6 | T10: 0 | V10: 737 | W10: 9 | X10: 6 | Y10: 0 | AA10: 765 | AB10: 4 | AC10: 10 | AD10: 1 | AF10: 591 | BA10: 8 | BB10: 7 | BC10: 0 | BE10: 783 | BZ10: 4 | CA10: 11 | CB10: 0 | CD10: 609 | CE10: 4 | CF10: 10 | CG10: 1 | CI10: 624 | CJ10: 11 | CK10: 4 | CL10: 0 | CN10: 879 | CZ10: 10 | DA10: =+G10+L10+Q10+V10+AA10+AF10+AK10+AP10+AU10+AZ10+BE10+BJ10+BO10+BT10+BY10+CD10+CI10+CN10+CS10+CX10 -> 7515 | DB10: =+DA10/CZ10 -> 751.5
A11: 1996 | C11: 6 | D11: 8 | E11: 1 | G11: 550 | H11: 13 | I11: 2 | J11: 0 | L11: 917 | M11: 6 | N11: 9 | O11: 0 | Q11: 620 | R11: 9 | S11: 6 | T11: 0 | V11: 913 | W11: 8 | X11: 7 | Y11: 0 | AA11: 730 | AB11: 4 | AC11: 10 | AD11: 1 | AF11: 541 | BA11: 8 | BB11: 7 | BC11: 0 | BE11: 888 | BZ11: 6 | CA11: 9 | CB11: 0 | CD11: 632 | CE11: 5 | CF11: 10 | CG11: 0 | CI11: 579 | CJ11: 9 | CK11: 6 | CL11: 0 | CN11: 815 | CZ11: 10 | DA11: =+G11+L11+Q11+V11+AA11+AF11+AK11+AP11+AU11+AZ11+BE11+BJ11+BO11+BT11+BY11+CD11+CI11+CN11+CS11+CX11 -> 7185 | DB11: =+DA11/CZ11 -> 718.5
A12: 1997 | C12: 3 | D12: 10 | E12: 2 | G12: 634 | H12: 8 | I12: 7 | J12: 0 | L12: 739 | M12: 6 | N12: 8 | O12: 1 | Q12: 691 | R12: 8 | S12: 7 | T12: 0 | V12: 808 | W12: 8 | X12: 6 | Y12: 1 | AA12: 720 | AB12: 6 | AC12: 9 | AD12: 0 | AF12: 607 | BA12: 10 | BB12: 5 | BC12: 0 | BE12: 699 | BZ12: 6 | CA12: 9 | CB12: 0 | CD12: 643 | CE12: 8 | CF12: 7 | CG12: 0 | CI12: 636 | CJ12: 10 | CK12: 5 | CL12: 0 | CN12: 829 | CZ12: 10 | DA12: =+G12+L12+Q12+V12+AA12+AF12+AK12+AP12+AU12+AZ12+BE12+BJ12+BO12+BT12+BY12+CD12+CI12+CN12+CS12+CX12 -> 7006 | DB12: =+DA12/CZ12 -> 700.6
A13: 1998 | C13: 2 | D13: 13 | E13: 0 | G13: 539 | H13: 10 | I13: 5 | J13: 0 | L13: 852 | M13: 10 | N13: 5 | O13: 0 | Q13: 934 | R13: 10 | S13: 5 | T13: 0 | V13: 932 | W13: 9 | X13: 6 | Y13: 0 | AA13: 716 | AB13: 7 | AC13: 8 | AD13: 0 | AF13: 629 | BA13: 8 | BB13: 7 | BC13: 0 | BE13: 774 | BZ13: 8 | CA13: 7 | CB13: 0 | CD13: 607 | CE13: 5 | CF13: 10 | CG13: 0 | CI13: 638 | CJ13: 6 | CK13: 9 | CL13: 0 | CN13: 595 | CZ13: 10 | DA13: =+G13+L13+Q13+V13+AA13+AF13+AK13+AP13+AU13+AZ13+BE13+BJ13+BO13+BT13+BY13+CD13+CI13+CN13+CS13+CX13 -> 7216 | DB13: =+DA13/CZ13 -> 721.6
A14: 1999 | C14: 7 | D14: 6 | E14: 2 | G14: 744 | H14: 8 | I14: 7 | J14: 0 | L14: 786 | M14: 9 | N14: 6 | O14: 0 | Q14: 718 | R14: 13 | S14: 2 | T14: 0 | V14: 902 | W14: 8 | X14: 6 | Y14: 1 | AA14: 744 | AB14: 5 | AC14: 9 | AD14: 1 | AF14: 617 | BA14: 6 | BB14: 9 | BC14: 0 | BE14: 537 | BZ14: 3 | CA14: 11 | CB14: 1 | CD14: 599 | CE14: 6 | CF14: 8 | CG14: 1 | CI14: 528 | CJ14: 7 | CK14: 8 | CL14: 0 | CN14: 677 | CZ14: 10 | DA14: =+G14+L14+Q14+V14+AA14+AF14+AK14+AP14+AU14+AZ14+BE14+BJ14+BO14+BT14+BY14+CD14+CI14+CN14+CS14+CX14 -> 6852 | DB14: =+DA14/CZ14 -> 685.2
A15: 2000 | C15: 7 | D15: 7 | E15: 1 | G15: 831 | H15: 9 | I15: 5 | J15: 1 | L15: 916 | M15: 10 | N15: 5 | O15: 0 | Q15: 924 | R15: 7 | S15: 8 | T15: 0 | V15: 743 | W15: 10 | X15: 4 | Y15: 1 | AA15: 974 | AB15: 8 | AC15: 6 | AD15: 1 | AF15: 890 | BA15: 7 | BB15: 8 | BC15: 0 | BE15: 648 | BZ15: 5 | CA15: 10 | CB15: 0 | CD15: 632 | CE15: 5 | CF15: 10 | CG15: 0 | CI15: 652 | CJ15: 5 | CK15: 10 | CL15: 0 | CN15: 616 | CZ15: 10 | DA15: =+G15+L15+Q15+V15+AA15+AF15+AK15+AP15+AU15+AZ15+BE15+BJ15+BO15+BT15+BY15+CD15+CI15+CN15+CS15+CX15 -> 7826 | DB15: =+DA15/CZ15 -> 782.6
A16: 2001 | C16: 6 | D16: 9 | E16: 0 | G16: 725 | H16: 13 | I16: 2 | J16: 0 | L16: 953 | M16: 8 | N16: 7 | O16: 0 | Q16: 801 | R16: 7 | S16: 8 | T16: 0 | V16: 817 | W16: 11 | X16: 4 | Y16: 0 | AA16: 816 | AB16: 11 | AC16: 4 | AD16: 0 | AF16: 809 | AG16: 3 | AH16: 12 | AI16: 0 | AK16: 526 | BA16: 6 | BB16: 9 | BC16: 0 | BE16: 653 | BZ16: 8 | CA16: 7 | CB16: 0 | CD16: 659 | CE16: 2 | CF16: 13 | CG16: 0 | CI16: 594 | CZ16: 10 | DA16: =+G16+L16+Q16+V16+AA16+AF16+AK16+AP16+AU16+AZ16+BE16+BJ16+BO16+BT16+BY16+CD16+CI16+CN16+CS16+CX16 -> 7353 | DB16: =+DA16/CZ16 -> 735.3
A17: 2002 | C17: 9 | D17: 6 | E17: 0 | G17: 764 | H17: 10 | I17: 5 | J17: 0 | L17: 886 | M17: 5 | N17: 10 | O17: 0 | Q17: 659 | R17: 10 | S17: 5 | T17: 0 | V17: 734 | W17: 5 | X17: 10 | Y17: 0 | AA17: 668 | AB17: 7 | AC17: 7 | AD17: 1 | AF17: 713 | AG17: 10 | AH17: 5 | AI17: 0 | AK17: 818 | AL17: 11 | AM17: 3 | AN17: 1 | AP17: 879 | AQ17: 7 | AR17: 8 | AS17: 0 | AU17: 717 | BA17: 4 | BB17: 11 | BC17: 0 | BE17: 615 | BZ17: 6 | CA17: 9 | CB17: 0 | CD17: 735 | CE17: 5 | CF17: 10 | CG17: 0 | CI17: 667 | CZ17: 12 | DA17: =+G17+L17+Q17+V17+AA17+AF17+AK17+AP17+AU17+AZ17+BE17+BJ17+BO17+BT17+BY17+CD17+CI17+CN17+CS17+CX17 -> 8855 | DB17: =+DA17/CZ17 -> 737.91667
A18: 2003 | C18: 12 | D18: 3 | E18: 0 | G18: 802 | H18: 11 | I18: 4 | J18: 0 | L18: 856 | M18: 8 | N18: 6 | O18: 1 | Q18: 779 | R18: 6 | S18: 9 | T18: 0 | V18: 772 | W18: 7 | X18: 8 | Y18: 0 | AA18: 812 | AB18: 11 | AC18: 4 | AD18: 0 | AF18: 887 | AG18: 3 | AH18: 11 | AI18: 1 | AK18: 675 | AL18: 7 | AM18: 6 | AN18: 2 | AP18: 707 | AQ18: 7 | AR18: 8 | AS18: 0 | AU18: 755 | BU18: 4 | BV18: 11 | BW18: 0 | BY18: 545 | BZ18: 7 | CA18: 8 | CB18: 0 | CD18: 613 | CE18: 5 | CF18: 10 | CG18: 0 | CI18: 602 | CZ18: 12 | DA18: =+G18+L18+Q18+V18+AA18+AF18+AK18+AP18+AU18+AZ18+BE18+BJ18+BO18+BT18+BY18+CD18+CI18+CN18+CS18+CX18 -> 8805 | DB18: =+DA18/CZ18 -> 733.75
A19: 2004 | C19: 6 | D19: 9 | E19: 0 | G19: 659 | H19: 10 | I19: 4 | J19: 1 | L19: 884 | M19: 9 | N19: 5 | O19: 1 | Q19: 912 | R19: 6 | S19: 9 | T19: 0 | V19: 756 | W19: 8 | X19: 7 | Y19: 0 | AA19: 777 | AB19: 7 | AC19: 8 | AD19: 0 | AF19: 669 | AG19: 5 | AH19: 10 | AI19: 0 | AK19: 595 | AL19: 8 | AM19: 6 | AN19: 1 | AP19: 771 | AQ19: 8 | AR19: 7 | AS19: 0 | AU19: 786 | BU19: 6 | BV19: 9 | BW19: 0 | BY19: 733 | BZ19: 6 | CA19: 8 | CB19: 1 | CD19: 774 | CE19: 9 | CF19: 6 | CG19: 0 | CI19: 865 | CZ19: 12 | DA19: =+G19+L19+Q19+V19+AA19+AF19+AK19+AP19+AU19+AZ19+BE19+BJ19+BO19+BT19+BY19+CD19+CI19+CN19+CS19+CX19 -> 9181 | DB19: =+DA19/CZ19 -> 765.08333
A20: 2005 | C20: 10 | D20: 4 | E20: 1 | G20: 853 | H20: 5 | I20: 10 | J20: 0 | L20: 762 | M20: 8 | N20: 7 | O20: 0 | Q20: 687 | R20: 5 | S20: 10 | T20: 0 | V20: 700 | W20: 8 | X20: 7 | Y20: 0 | AA20: 629 | AB20: 8 | AC20: 6 | AD20: 1 | AF20: 762 | AG20: 4 | AH20: 11 | AI20: 0 | AK20: 547 | AL20: 6 | AM20: 7 | AN20: 2 | AP20: 686 | AQ20: 9 | AR20: 6 | AS20: 0 | AU20: 918 | BU20: 7 | BV20: 8 | BW20: 0 | BY20: 572 | BZ20: 11 | CA20: 4 | CB20: 0 | CD20: 797 | CE20: 7 | CF20: 8 | CG20: 0 | CI20: 650 | CZ20: 12 | DA20: =+G20+L20+Q20+V20+AA20+AF20+AK20+AP20+AU20+AZ20+BE20+BJ20+BO20+BT20+BY20+CD20+CI20+CN20+CS20+CX20 -> 8563 | DB20: =+DA20/CZ20 -> 713.58333
A21: 2006 | C21: 6 | D21: 8 | E21: 0 | G21: 839 | H21: 10 | I21: 4 | J21: 0 | L21: 856 | M21: 7 | N21: 7 | O21: 0 | Q21: 629 | R21: 7 | S21: 7 | T21: 0 | V21: 635 | W21: 6 | X21: 8 | Y21: 0 | AA21: 615 | AB21: 11 | AC21: 3 | AD21: 0 | AF21: 744 | AG21: 3 | AH21: 11 | AI21: 0 | AK21: 531 | AL21: 5 | AM21: 9 | AN21: 0 | AP21: 600 | AQ21: 9 | AR21: 5 | AS21: 0 | AU21: 653 | AV21: 9 | AW21: 5 | AX21: 0 | AZ21: 766 | BU21: 7 | BV21: 7 | BW21: 0 | BY21: 683 | BZ21: 4 | CA21: 10 | CB21: 0 | CD21: 559 | CZ21: 12 | DA21: =+G21+L21+Q21+V21+AA21+AF21+AK21+AP21+AU21+AZ21+BE21+BJ21+BO21+BT21+BY21+CD21+CI21+CN21+CS21+CX21 -> 8110 | DB21: =+DA21/CZ21 -> 675.83333
A22: 2007 | C22: 4 | D22: 10 | E22: 0 | G22: 740 | H22: 5 | I22: 8 | J22: 1 | L22: 720 | M22: 7 | N22: 7 | O22: 0 | Q22: 718 | R22: 9 | S22: 5 | T22: 0 | V22: 721 | W22: 5 | X22: 9 | Y22: 0 | AA22: 512 | AB22: 13 | AC22: 1 | AD22: 0 | AF22: 1000 | AG22: 4 | AH22: 9 | AI22: 1 | AK22: 501 | AL22: 5 | AM22: 9 | AN22: 0 | AP22: 608 | AQ22: 5 | AR22: 8 | AS22: 1 | AU22: 582 | AV22: 9 | AW22: 5 | AX22: 0 | AZ22: 802 | BU22: 10 | BV22: 3 | BW22: 1 | BY22: 834 | BZ22: 6 | CA22: 8 | CB22: 0 | CD22: 665 | CZ22: 12 | DA22: =+G22+L22+Q22+V22+AA22+AF22+AK22+AP22+AU22+AZ22+BE22+BJ22+BO22+BT22+BY22+CD22+CI22+CN22+CS22+CX22 -> 8403 | DB22: =+DA22/CZ22 -> 700.25
A23: 2008 | C23: 8 | D23: 6 | E23: 0 | G23: 678 | H23: 11 | I23: 3 | J23: 0 | L23: 704 | M23: 11 | N23: 3 | O23: 0 | Q23: 822 | R23: 5 | S23: 9 | T23: 0 | V23: 725 | W23: 1 | X23: 12 | Y23: 1 | AA23: 455 | AB23: 5 | AC23: 9 | AD23: 0 | AF23: 671 | AG23: 10 | AH23: 4 | AI23: 0 | AK23: 725 | AL23: 2 | AM23: 12 | AN23: 0 | AP23: 530 | AQ23: 10 | AR23: 4 | AS23: 0 | AU23: 711 | AV23: 8 | AW23: 6 | AX23: 0 | AZ23: 788 | BU23: 7 | BV23: 7 | BW23: 0 | BY23: 770 | BZ23: 5 | CA23: 8 | CB23: 1 | CD23: 640 | CZ23: 12 | DA23: =+G23+L23+Q23+V23+AA23+AF23+AK23+AP23+AU23+AZ23+BE23+BJ23+BO23+BT23+BY23+CD23+CI23+CN23+CS23+CX23 -> 8219 | DB23: =+DA23/CZ23 -> 684.91667
A24: 2009 | C24: 6 | D24: 8 | E24: 0 | F24: 7 | G24: 725 | H24: 10 | I24: 4 | J24: 0 | K24: 10 | L24: 835 | M24: 11 | N24: 3 | O24: 0 | P24: 9 | Q24: 844 | R24: 2 | S24: 12 | T24: 0 | U24: 4.5 | V24: 604 | W24: 6 | X24: 8 | Y24: 0 | Z24: 3 | AA24: 626 | AB24: 5 | AC24: 9 | AD24: 0 | AE24: 6 | AF24: 719 | AG24: 12 | AH24: 2 | AI24: 0 | AJ24: 11 | AK24: 805 | AL24: 2 | AM24: 12 | AN24: 0 | AO24: 2.5 | AP24: 540 | AQ24: 6 | AR24: 8 | AS24: 0 | AT24: 8 | AU24: 698 | AV24: 6 | AW24: 8 | AX24: 0 | AY24: 8.5 | AZ24: 791 | BA24: 10 | BB24: 4 | BC24: 0 | BD24: 7.5 | BE24: 715 | BF24: 8 | BG24: 6 | BH24: 0 | BI24: 7 | BJ24: 723 | CZ24: 12 | DA24: =+G24+L24+Q24+V24+AA24+AF24+AK24+AP24+AU24+AZ24+BE24+BJ24+BO24+BT24+BY24+CD24+CI24+CN24+CS24+CX24 -> 8625 | DB24: =+DA24/CZ24 -> 718.75
A25: 2010 | C25: 4 | D25: 10 | E25: 0 | F25: 5 | G25: 659 | H25: 8 | I25: 6 | J25: 0 | K25: 10 | L25: 808 | M25: 10 | N25: 4 | O25: 0 | P25: 9.7 | Q25: 802 | R25: 4 | S25: 8 | T25: 2 | U25: 5.7 | V25: 585 | W25: 3 | X25: 11 | Y25: 0 | Z25: 6 | AA25: 674 | AB25: 10 | AC25: 3 | AD25: 1 | AE25: 9.7 | AF25: 864 | AG25: 8 | AH25: 6 | AI25: 0 | AJ25: 3 | AK25: 606 | AL25: 3 | AM25: 9 | AN25: 2 | AO25: 5 | AP25: 620 | AQ25: 8 | AR25: 6 | AS25: 0 | AT25: 8 | AU25: 689 | AV25: 8 | AW25: 6 | AX25: 0 | AY25: 8 | AZ25: 695 | BA25: 7 | BB25: 6 | BC25: 1 | BD25: 7 | BE25: 665 | BF25: 8 | BG25: 6 | BH25: 0 | BI25: 7 | BJ25: 717 | CZ25: 12 | DA25: =+G25+L25+Q25+V25+AA25+AF25+AK25+AP25+AU25+AZ25+BE25+BJ25+BO25+BT25+BY25+CD25+CI25+CN25+CS25+CX25 -> 8384 | DB25: =+DA25/CZ25 -> 698.66667
A26: 2011 | C26: 6 | D26: 8 | E26: 0 | F26: 9 | G26: 717 | H26: 6 | I26: 8 | J26: 0 | K26: 5 | L26: 638 | M26: 8 | N26: 6 | O26: 0 | P26: 9 | Q26: 828 | R26: 5 | S26: 9 | T26: 0 | U26: 5 | V26: 739 | W26: 8 | X26: 6 | Y26: 0 | Z26: 8 | AA26: 769 | AB26: 11 | AC26: 3 | AD26: 0 | AE26: 11 | AF26: 841 | AG26: 9 | AH26: 5 | AI26: 0 | AJ26: 7 | AK26: 728 | AL26: 6 | AM26: 8 | AN26: 0 | AO26: 7.5 | AP26: 703 | AQ26: 5 | AR26: 9 | AS26: 0 | AT26: 3.5 | AU26: 654 | AV26: 5 | AW26: 9 | AX26: 0 | AY26: 7 | AZ26: 710 | BA26: 9 | BB26: 5 | BC26: 0 | BD26: 7.5 | BE26: 731 | BF26: 6 | BG26: 8 | BH26: 0 | BI26: 4 | BJ26: 704 | CZ26: 12 | DA26: =+G26+L26+Q26+V26+AA26+AF26+AK26+AP26+AU26+AZ26+BE26+BJ26+BO26+BT26+BY26+CD26+CI26+CN26+CS26+CX26 -> 8762 | DB26: =+DA26/CZ26 -> 730.16667
A27: 2012 | C27: 9 | D27: 5 | E27: 0 | F27: 9 | G27: 745 | H27: 11 | I27: 3 | J27: 0 | K27: 11 | L27: 842 | M27: 8 | N27: 6 | O27: 0 | P27: 6 | Q27: 692 | R27: 6 | S27: 8 | T27: 0 | U27: 7 | V27: 669 | W27: 7 | X27: 7 | Y27: 0 | Z27: 5 | AA27: 689 | AB27: 8 | AC27: 6 | AD27: 0 | AE27: 7.5 | AF27: 782 | AG27: 5 | AH27: 8 | AI27: 1 | AJ27: 5 | AK27: 736 | AL27: 5 | AM27: 9 | AN27: 0 | AO27: 7 | AP27: 682 | AQ27: 6 | AR27: 8 | AS27: 0 | AT27: 6.5 | AU27: 712 | AV27: 8 | AW27: 6 | AX27: 0 | AY27: 7.5 | AZ27: 741 | BA27: 5 | BB27: 9 | BC27: 0 | BD27: 5 | BE27: 641 | BF27: 5 | BG27: 8 | BH27: 1 | BI27: 7.5 | BJ27: 740 | CZ27: 12 | DA27: =+G27+L27+Q27+V27+AA27+AF27+AK27+AP27+AU27+AZ27+BE27+BJ27+BO27+BT27+BY27+CD27+CI27+CN27+CS27+CX27 -> 8671 | DB27: =+DA27/CZ27 -> 722.58333 | DC27: =SUM(DB3:DB27) -> 17337.95 | DD27: =+DC27/25 -> 693.518
A28: 2013 | C28: 10 | D28: 4 | E28: 0 | F28: 9 | G28: 779 | H28: 8 | I28: 6 | J28: 0 | K28: 9 | L28: 717 | M28: 10 | N28: 4 | O28: 0 | P28: 9 | Q28: 722 | R28: 7 | S28: 7 | T28: 0 | U28: 6 | V28: 589 | W28: 7 | X28: 6 | Y28: 1 | Z28: 8 | AA28: 623 | AB28: 4 | AC28: 10 | AD28: 0 | AE28: 5 | AF28: 611 | AG28: 6 | AH28: 8 | AI28: 0 | AJ28: 7 | AK28: 700 | AL28: 9 | AM28: 5 | AN28: 0 | AO28: 9 | AP28: 776 | AQ28: 7 | AR28: 7 | AS28: 0 | AT28: 11 | AU28: 791 | AV28: 7 | AW28: 6 | AX28: 1 | AY28: 7 | AZ28: 682 | BA28: 5 | BB28: 9 | BC28: 0 | BD28: 3 | BE28: 479 | BF28: 3 | BG28: 11 | BH28: 0 | BI28: 1 | BJ28: 433 | CZ28: 12 | DA28: =+G28+L28+Q28+V28+AA28+AF28+AK28+AP28+AU28+AZ28+BE28+BJ28+BO28+BT28+BY28+CD28+CI28+CN28+CS28+CX28 -> 7902 | DB28: =+DA28/CZ28 -> 658.5 | DE28: =+DB28/14 -> 47.035714
A29: 2014 | C29: 6 | D29: 7 | E29: 1 | F29: 8.5 | G29: 744 | H29: 8 | I29: 6 | J29: 0 | K29: 8 | L29: 746 | M29: 9 | N29: 5 | O29: 0 | P29: 11.5 | Q29: 783 | R29: 5 | S29: 9 | T29: 0 | U29: 6 | V29: 677 | W29: 6 | X29: 7 | Y29: 1 | Z29: 6.5 | AA29: 673 | AB29: 10 | AC29: 3 | AD29: 1 | AE29: 11.5 | AF29: 824 | AG29: 8 | AH29: 6 | AI29: 0 | AJ29: 6 | AK29: 711 | AL29: 4 | AM29: 9 | AN29: 1 | AO29: 4.5 | AP29: 676 | AQ29: 8 | AR29: 6 | AS29: 0 | AT29: 6.5 | AU29: 696 | AV29: 7 | AW29: 7 | AX29: 0 | AY29: 6 | AZ29: 654 | BA29: 8 | BB29: 6 | BC29: 0 | BD29: 6.5 | BE29: 700 | BF29: 3 | BG29: 11 | BH29: 0 | BI29: 2.5 | BJ29: 505 | CZ29: 12 | DA29: =+G29+L29+Q29+V29+AA29+AF29+AK29+AP29+AU29+AZ29+BE29+BJ29+BO29+BT29+BY29+CD29+CI29+CN29+CS29+CX29 -> 8389 | DB29: =+DA29/CZ29 -> 699.08333 | DE29: =+DB29/14 -> 49.934524
A30: 2015 | C30: 8 | D30: 6 | E30: 0 | F30: 8 | G30: 656 | H30: 6 | I30: 8 | J30: 0 | K30: 2 | L30: 493 | M30: 9 | N30: 5 | O30: 0 | P30: 8 | Q30: 760 | R30: 5 | S30: 9 | T30: 0 | U30: 8.5 | V30: 698 | W30: 8 | X30: 6 | Y30: 0 | Z30: 7 | AA30: 721 | AB30: 8 | AC30: 6 | AD30: 0 | AE30: 10 | AF30: 713 | AG30: 10 | AH30: 4 | AI30: 0 | AJ30: 9 | AK30: 703 | AL30: 7 | AM30: 6 | AN30: 1 | AO30: 10 | AP30: 693 | AQ30: 7 | AR30: 7 | AS30: 0 | AT30: 7.5 | AU30: 660 | AV30: 7 | AW30: 7 | AX30: 0 | AY30: 7 | AZ30: 638 | BA30: 5 | BB30: 9 | BC30: 0 | BD30: 3 | BE30: 526 | BF30: 3 | BG30: 10 | BH30: 1 | BI30: 4 | BJ30: 559 | CZ30: 12 | DA30: =+G30+L30+Q30+V30+AA30+AF30+AK30+AP30+AU30+AZ30+BE30+BJ30+BO30+BT30+BY30+CD30+CI30+CN30+CS30+CX30 -> 7820 | DB30: =+DA30/CZ30 -> 651.66667 | DE30: =+DB30/14 -> 46.547619
A31: 2016 | C31: 11 | D31: 3 | E31: 0 | F31: 8.5 | G31: 690 | H31: 3 | I31: 11 | J31: 0 | K31: 1.5 | L31: 499 | M31: 6 | N31: 7 | O31: 1 | P31: 10 | Q31: 692 | R31: 9 | S31: 5 | T31: 0 | U31: 10 | V31: 702 | W31: 9 | X31: 4 | Y31: 1 | Z31: 8.5 | AA31: 725 | AB31: 5 | AC31: 9 | AD31: 0 | AE31: 8.5 | AF31: 719 | AG31: 7 | AH31: 7 | AI31: 0 | AJ31: 5.5 | AK31: 649 | AL31: 8 | AM31: 6 | AN31: 0 | AO31: 7.5 | AP31: 650 | AQ31: 4 | AR31: 9 | AS31: 1 | AT31: 5.5 | AU31: 554 | AV31: 8 | AW31: 6 | AX31: 0 | AY31: 8 | AZ31: 696 | BA31: 3 | BB31: 9 | BC31: 2 | BD31: 3 | BE31: 524 | BF31: 8 | BG31: 5 | BH31: 1 | BI31: 7.5 | BJ31: 691 | CZ31: 12 | DA31: =+G31+L31+Q31+V31+AA31+AF31+AK31+AP31+AU31+AZ31+BE31+BJ31+BO31+BT31+BY31+CD31+CI31+CN31+CS31+CX31 -> 7791 | DB31: =+DA31/CZ31 -> 649.25 | DE31: =+DB31/14 -> 46.375
A32: 2017 | C32: 5 | D32: 9 | E32: 0 | F32: 9 | G32: 702 | H32: 5 | I32: 9 | J32: 0 | K32: 7 | L32: 622 | M32: 10 | N32: 4 | O32: 0 | P32: 7 | Q32: 615 | R32: 5 | S32: 8 | T32: 1 | U32: 6 | V32: 622 | W32: 6 | X32: 7 | Y32: 1 | Z32: 5 | AA32: 588 | AB32: 10 | AC32: 4 | AD32: 0 | AE32: 10 | AF32: 769 | AG32: 10 | AH32: 3 | AI32: 1 | AJ32: 8.5 | AK32: 678 | AL32: 3 | AM32: 11 | AN32: 0 | AO32: 5 | AP32: 531 | AQ32: 6 | AR32: 7 | AS32: 1 | AT32: 8.5 | AU32: 672 | AV32: 8 | AW32: 6 | AX32: 0 | AY32: 7 | AZ32: 617 | BA32: 5 | BB32: 9 | BC32: 0 | BD32: 3.5 | BE32: 557 | BF32: 9 | BG32: 5 | BH32: 0 | BI32: 7.5 | BJ32: 630 | CZ32: 12 | DA32: =+G32+L32+Q32+V32+AA32+AF32+AK32+AP32+AU32+AZ32+BE32+BJ32+BO32+BT32+BY32+CD32+CI32+CN32+CS32+CX32 -> 7603 | DB32: =+DA32/CZ32 -> 633.58333 | DE32: =+DB32/14 -> 45.255952
A33: 2018 | C33: 8 | D33: 6 | E33: 0 | F33: 6 | G33: 676 | H33: 4 | I33: 10 | J33: 0 | K33: 3 | L33: 595 | M33: 11 | N33: 3 | O33: 0 | P33: 12 | Q33: 896 | R33: 10 | S33: 4 | T33: 0 | U33: 5 | V33: 731 | W33: 5 | X33: 9 | Y33: 0 | Z33: 7 | AA33: 687 | AB33: 9 | AC33: 5 | AD33: 0 | AE33: 9.67 | AF33: 831 | AG33: 6 | AH33: 8 | AI33: 0 | AJ33: 4 | AK33: 685 | AL33: 8 | AM33: 5 | AN33: 1 | AO33: 9.67 | AP33: 791 | AQ33: 8 | AR33: 6 | AS33: 0 | AT33: 10 | AU33: 856 | AV33: 6 | AW33: 7 | AX33: 1 | AY33: 8 | AZ33: 746 | BA33: 3 | BB33: 11 | BC33: 0 | BD33: 5 | BE33: 638 | BF33: 5 | BG33: 9 | BH33: 0 | BI33: 4.67 | BJ33: 600 | CZ33: 12 | DA33: =+G33+L33+Q33+V33+AA33+AF33+AK33+AP33+AU33+AZ33+BE33+BJ33+BO33+BT33+BY33+CD33+CI33+CN33+CS33+CX33 -> 8732 | DB33: =+DA33/CZ33 -> 727.66667 | DE33: =+DB33/14 -> 51.97619
A34: 2019 | C34: 6 | D34: 8 | E34: 0 | F34: 7 | G34: 682 | H34: 8 | I34: 6 | J34: 0 | K34: 4 | L34: 632 | M34: 8 | N34: 6 | O34: 0 | P34: 7 | Q34: 683 | R34: 6 | S34: 8 | T34: 0 | U34: 7 | V34: 633 | W34: 5 | X34: 9 | Y34: 0 | Z34: 6 | AA34: 698 | AB34: 9 | AC34: 5 | AD34: 0 | AE34: 7 | AF34: 719 | AG34: 5 | AH34: 9 | AI34: 0 | AJ34: 8 | AK34: 740 | AL34: 7 | AM34: 7 | AN34: 0 | AO34: 7 | AP34: 723 | AQ34: 7 | AR34: 7 | AS34: 0 | AT34: 8 | AU34: 737 | AV34: 6 | AW34: 8 | AX34: 0 | AY34: 6 | AZ34: 626 | BA34: 6 | BB34: 8 | BC34: 0 | BD34: 4 | BE34: 642 | BF34: 11 | BG34: 3 | BH34: 0 | BI34: 13 | BJ34: 838 | CZ34: 12 | DA34: =+G34+L34+Q34+V34+AA34+AF34+AK34+AP34+AU34+AZ34+BE34+BJ34+BO34+BT34+BY34+CD34+CI34+CN34+CS34+CX34 -> 8353 | DB34: =+DA34/CZ34 -> 696.08333 | DC34: =SUM(DB28:DB34) -> 4715.8333 | DD34: =+DC34/7 -> 673.69048 | DE34: =+DB34/14 -> 49.720238
A35: 2020 | C35: 9 | D35: 5 | E35: 0 | F35: 9 | G35: 809 | H35: 7 | I35: 7 | J35: 0 | K35: 8 | L35: 657 | M35: 3 | N35: 11 | O35: 0 | P35: 4 | Q35: 668 | R35: 7 | S35: 7 | T35: 0 | U35: 6.5 | V35: 751 | W35: 10 | X35: 4 | Y35: 0 | Z35: 9 | AA35: 902 | AB35: 9 | AC35: 5 | AD35: 0 | AE35: 9 | AF35: 768 | AG35: 8 | AH35: 6 | AI35: 0 | AJ35: 9 | AK35: 817 | AL35: 3 | AM35: 11 | AN35: 0 | AO35: 6 | AP35: 680 | AQ35: 10 | AR35: 4 | AS35: 0 | AT35: 9 | AU35: 819 | AV35: 9 | AW35: 5 | AX35: 0 | AY35: 7 | AZ35: 753 | BA35: 6 | BB35: 8 | BC35: 0 | BD35: 5.5 | BE35: 742 | BF35: 3 | BG35: 11 | BH35: 0 | BI35: 2 | BJ35: 582 | CZ35: 12 | DA35: =+G35+L35+Q35+V35+AA35+AF35+AK35+AP35+AU35+AZ35+BE35+BJ35+BO35+BT35+BY35+CD35+CI35+CN35+CS35+CX35 -> 8948 | DB35: =+DA35/CZ35 -> 745.66667 | DC35: =SUM(DB28:DB35) -> 5461.5 | DD35: =+DC35/8 -> 682.6875 | DE35: =+DB35/14 -> 53.261905
A36: 2021 | C36: 8 | D36: 7 | E36: 0 | F36: 9 | G36: 751 | H36: 7 | I36: 8 | J36: 0 | K36: 8 | L36: 747 | M36: 4 | N36: 10 | O36: 1 | P36: 7 | Q36: 670 | R36: 10 | S36: 5 | T36: 0 | U36: 8 | V36: 744 | W36: 11 | X36: 4 | Y36: 0 | Z36: 11 | AA36: 864 | AB36: 6 | AC36: 8 | AD36: 1 | AE36: 4 | AF36: 751 | AG36: 9 | AH36: 5 | AI36: 1 | AJ36: 9 | AK36: 806 | AL36: 5 | AM36: 9 | AN36: 1 | AO36: 3 | AP36: 574 | AQ36: 7 | AR36: 8 | AS36: 0 | AT36: 9 | AU36: 864 | AV36: 8 | AW36: 5 | AX36: 2 | AY36: 9 | AZ36: 788 | BF36: 6 | BG36: 9 | BH36: 0 | BI36: 7 | BJ36: 710 | BK36: 6 | BL36: 9 | BM36: 0 | BN36: 6 | BO36: 702 | CZ36: 12 | DA36: =+G36+L36+Q36+V36+AA36+AF36+AK36+AP36+AU36+AZ36+BE36+BJ36+BO36+BT36+BY36+CD36+CI36+CN36+CS36+CX36 -> 8971 | DB36: =+DA36/CZ36 -> 747.58333 | DC36: =SUM(DB28:DB36) -> 6209.0833 | DD36: =+DC36/9 -> 689.89815 | DE36: =+DB36/15 -> 49.838889
A37: 2022 | H37: 11 | I37: 4 | J37: 0 | K37: 10 | L37: 755 | M37: 4 | N37: 9 | O37: 2 | P37: 5 | Q37: 603 | R37: 3 | S37: 12 | T37: 0 | U37: 3 | V37: 509 | W37: 12 | X37: 3 | Y37: 0 | Z37: 10 | AA37: 769 | AB37: 8 | AC37: 7 | AD37: 0 | AE37: 9 | AF37: 744 | AG37: 6 | AH37: 7 | AI37: 2 | AJ37: 9.5 | AK37: 776 | AL37: 4 | AM37: 10 | AN37: 1 | AO37: 2 | AP37: 573 | AQ37: 8 | AR37: 5 | AS37: 2 | AT37: 12.5 | AU37: 857 | AV37: 7 | AW37: 8 | AX37: 0 | AY37: 4.5 | AZ37: 595 | BF37: 6 | BG37: 9 | BH37: 0 | BI37: 8 | BJ37: 761 | BK37: 9 | BL37: 6 | BM37: 0 | BN37: 8 | BO37: 760 | BP37: 8 | BQ37: 6 | BR37: 1 | BS37: 8.5 | BT37: 730 | CZ37: 12 | DA37: =+G37+L37+Q37+V37+AA37+AF37+AK37+AP37+AU37+AZ37+BE37+BJ37+BO37+BT37+BY37+CD37+CI37+CN37+CS37+CX37 -> 8432 | DB37: =+DA37/CZ37 -> 702.66667 | DC37: =SUM(DB28:DB37) -> 6911.75 | DD37: =+DC37/10 -> 691.175 | DE37: =+DB37/15 -> 46.844444
A38: 2023 | H38: 6 | I38: 9 | J38: 0 | K38: 5 | L38: 673 | M38: 10 | N38: 4 | O38: 1 | P38: 6 | Q38: 705 | R38: 9 | S38: 5 | T38: 1 | U38: 7 | V38: 615 | W38: 8 | X38: 7 | Y38: 0 | Z38: 10 | AA38: 851 | AB38: 3 | AC38: 12 | AD38: 0 | AE38: 6 | AF38: 740 | AG38: 9 | AH38: 4 | AI38: 2 | AJ38: 10 | AK38: 786 | AL38: 5 | AM38: 10 | AN38: 0 | AO38: 6 | AP38: 645 | AQ38: 10 | AR38: 5 | AS38: 0 | AT38: 12 | AU38: 814 | AV38: 8 | AW38: 6 | AX38: 1 | AY38: 11 | AZ38: 825 | BF38: 8 | BG38: 6 | BH38: 1 | BI38: 9 | BJ38: 700 | BK38: 7 | BL38: 8 | BM38: 0 | BN38: 3 | BO38: 588 | BP38: 4 | BQ38: 11 | BR38: 0 | BS38: 5 | BT38: 648 | CZ38: 12 | DA38: =+G38+L38+Q38+V38+AA38+AF38+AK38+AP38+AU38+AZ38+BE38+BJ38+BO38+BT38+BY38+CD38+CI38+CN38+CS38+CX38 -> 8590 | DB38: =+DA38/CZ38 -> 715.83333 | DC38: =SUM(DB28:DB38) -> 7627.5833 | DD38: =+DC38/11 -> 693.41667 | DE38: =+DB38/15 -> 47.722222
A39: 2024 | H39: 9 | I39: 6 | J39: 0 | K39: 9 | L39: 781 | M39: 9 | N39: 6 | O39: 0 | P39: 8.5 | Q39: 726 | R39: 5 | S39: 9 | T39: 1 | U39: 2.5 | V39: 623 | W39: 9 | X39: 6 | Y39: 0 | Z39: 12 | AA39: 972 | AB39: 8 | AC39: 7 | AD39: 0 | AE39: 7 | AF39: 702 | AG39: 6 | AH39: 9 | AI39: 0 | AJ39: 6.5 | AK39: 710 | AL39: 3 | AM39: 12 | AN39: 0 | AO39: 5 | AP39: 661 | AQ39: 10 | AR39: 5 | AS39: 0 | AT39: 10 | AU39: 802 | AV39: 9 | AW39: 6 | AX39: 0 | AY39: 9 | AZ39: 751 | BF39: 6 | BG39: 9 | BH39: 0 | BI39: 6 | BJ39: 735 | BK39: 11 | BL39: 4 | BM39: 0 | BN39: 10 | BO39: 865 | BP39: 4 | BQ39: 10 | BR39: 1 | BS39: 4.5 | BT39: 699 | CZ39: 12 | DA39: =+G39+L39+Q39+V39+AA39+AF39+AK39+AP39+AU39+AZ39+BE39+BJ39+BO39+BT39+BY39+CD39+CI39+CN39+CS39+CX39 -> 9027 | DB39: =+DA39/CZ39 -> 752.25 | DC39: =SUM(DB28:DB39) -> 8379.8333 | DD39: =+DC39/12 -> 698.31944 | DE39: =+DB39/15 -> 50.15
A41: Total | C41: =SUM(C3:C40) -> 240 | D41: =SUM(D3:D40) -> 244 | E41: =SUM(E3:E40) -> 10 | F41: =SUM(F3:F40) -> 104 | G41: =SUM(G3:G40) -> 23942 | H41: =SUM(H3:H40) -> 308 | I41: =SUM(I3:I40) -> 224 | J41: =SUM(J3:J40) -> 7 | ... CX41: =SUM(CX3:CX40) -> 482 | CZ41: =SUM(CZ3:CZ40) -> 414
...
